Workbook

Sheet Asset Data_Initial Contract
A1: Month of Period Start | B1: Machine ID:SERIAL # | C1: Sum of Coin In | D1: Sum of Net Win | E1: Net Win_2 (Players Reward deducted) | F1: EGM Day Count | G1: WPUPD | H1: Fee/Revenue | I1: Distinct Ser# Count | J1: Revenue Share | K1: ='Fee Initial Contract'!F18 -> 0.14123422 | M1: OPAP's Players Reward Scheme cost | N1: 3769.7781 | O1: OPAP's Players Reward Scheme cost per machine | P1: =N1/I5731 -> 0.65801677
A2: 45962 | B2: 2253017 | C2: 4578 | D2: 496.37 | E2: =D2-$P$1 -> 495.71198 | F2: 30 | G2: =D2/F2 -> 16.545667 | H2: =E2*$K$1 -> 70.011494 | I2: 1
A3: 45962 | B3: 2253103 | C3: 18328 | D3: 1005.18 | E3: =D3-$P$1 -> 1004.522 | F3: 30 | G3: =D3/F3 -> 33.506 | H3: =E3*$K$1 -> 141.87288 | I3: 1
A4: 45962 | B4: 2253112 | C4: 1855 | D4: 286.36 | E4: =D4-$P$1 -> 285.70198 | F4: 6 | G4: =D4/F4 -> 47.726667 | H4: =E4*$K$1 -> 40.350896 | I4: 1
A5: 45962 | B5: 2253118 | C5: 5071 | D5: -22.79 | E5: =D5-$P$1 -> -23.448017 | F5: 30 | G5: =D5/F5 -> -0.75966667 | H5: =E5*$K$1 -> -3.3116623 | I5: 1
A6: 45962 | B6: 2253119 | C6: 2965 | D6: -401.75 | E6: =D6-$P$1 -> -402.40802 | F6: 30 | G6: =D6/F6 -> -13.391667 | H6: =E6*$K$1 -> -56.833782 | I6: 1
A7: 45962 | B7: 2377541 | C7: 2811 | D7: 216.25 | E7: =D7-$P$1 -> 215.59198 | F7: 30 | G7: =D7/F7 -> 7.2083333 | H7: =E7*$K$1 -> 30.448965 | I7: 1
A8: 45962 | B8: 2377544 | C8: 1063 | D8: 119.95 | E8: =D8-$P$1 -> 119.29198 | F8: 30 | G8: =D8/F8 -> 3.9983333 | H8: =E8*$K$1 -> 16.84811 | I8: 1
A9: 45962 | B9: 2377547 | C9: 646 | D9: -66.04 | E9: =D9-$P$1 -> -66.698017 | F9: 17 | G9: =D9/F9 -> -3.8847059 | H9: =E9*$K$1 -> -9.4200423 | I9: 1
A10: 45962 | B10: 2377554 | C10: 1418 | D10: 173.68 | E10: =D10-$P$1 -> 173.02198 | F10: 25 | G10: =D10/F10 -> 6.9472 | H10: =E10*$K$1 -> 24.436625 | I10: 1
A11: 45962 | B11: 2377555 | C11: 294 | D11: -6.82 | E11: =D11-$P$1 -> -7.4780168 | F11: 26 | G11: =D11/F11 -> -0.26230769 | H11: =E11*$K$1 -> -1.0561519 | I11: 1
A12: 45962 | B12: 2377556 | C12: 378 | D12: -309.12 | E12: =D12-$P$1 -> -309.77802 | F12: 30 | G12: =D12/F12 -> -10.304 | H12: =E12*$K$1 -> -43.751256 | I12: 1
A13: 45962 | B13: 2377557 | C13: 2493 | D13: -391.12 | E13: =D13-$P$1 -> -391.77802 | F13: 25 | G13: =D13/F13 -> -15.6448 | H13: =E13*$K$1 -> -55.332462 | I13: 1
A14: 45962 | B14: 2377561 | C14: 0 | E14: =D14-$P$1 -> -0.65801677 | F14: 30 | G14: =D14/F14 -> 0 | H14: =E14*$K$1 -> -0.092934485 | I14: 1
A15: 45962 | B15: 2377562 | C15: 10828 | D15: 174.48 | E15: =D15-$P$1 -> 173.82198 | F15: 30 | G15: =D15/F15 -> 5.816 | H15: =E15*$K$1 -> 24.549612 | I15: 1
A16: 45962 | B16: 2377567 | C16: 12516 | D16: 1991.69 | E16: =D16-$P$1 -> 1991.032 | F16: 30 | G16: =D16/F16 -> 66.389667 | H16: =E16*$K$1 -> 281.20185 | I16: 1
A17: 45962 | B17: 2377573 | C17: 14695 | D17: 416.78 | E17: =D17-$P$1 -> 416.12198 | F17: 30 | G17: =D17/F17 -> 13.892667 | H17: =E17*$K$1 -> 58.770663 | I17: 1
A18: 45962 | B18: 2377575 | C18: 2269 | D18: 521.2 | E18: =D18-$P$1 -> 520.54198 | F18: 17 | G18: =D18/F18 -> 30.658824 | H18: =E18*$K$1 -> 73.51834 | I18: 1
A19: 45962 | B19: 2377579 | C19: 209 | D19: 99.48 | E19: =D19-$P$1 -> 98.821983 | F19: 12 | G19: =D19/F19 -> 8.29 | H19: =E19*$K$1 -> 13.957046 | I19: 1
A20: 45962 | B20: 2377582 | C20: 11817 | D20: 8.62 | E20: =D20-$P$1 -> 7.9619832 | F20: 30 | G20: =D20/F20 -> 0.28733333 | H20: =E20*$K$1 -> 1.1245045 | I20: 1
A21: 45962 | B21: 2377593 | C21: 121 | D21: 36.13 | E21: =D21-$P$1 -> 35.471983 | F21: 30 | G21: =D21/F21 -> 1.2043333 | H21: =E21*$K$1 -> 5.0098578 | I21: 1
A22: 45962 | B22: 2377612 | C22: 0 | E22: =D22-$P$1 -> -0.65801677 | F22: 7 | G22: =D22/F22 -> 0 | H22: =E22*$K$1 -> -0.092934485 | I22: 1
A23: 45962 | B23: 2377631 | C23: 1079 | D23: -140.1 | E23: =D23-$P$1 -> -140.75802 | F23: 17 | G23: =D23/F23 -> -8.2411765 | H23: =E23*$K$1 -> -19.879848 | I23: 1
A24: 45962 | B24: 2377633 | C24: 221 | D24: 93.94 | E24: =D24-$P$1 -> 93.281983 | F24: 17 | G24: =D24/F24 -> 5.5258824 | H24: =E24*$K$1 -> 13.174608 | I24: 1
A25: 45962 | B25: 2377636 | C25: 3195 | D25: 459.02 | E25: =D25-$P$1 -> 458.36198 | F25: 13 | G25: =D25/F25 -> 35.309231 | H25: =E25*$K$1 -> 64.736396 | I25: 1
A26: 45962 | B26: 2377648 | C26: 1656 | D26: 292.04 | E26: =D26-$P$1 -> 291.38198 | F26: 29 | G26: =D26/F26 -> 10.070345 | H26: =E26*$K$1 -> 41.153107 | I26: 1
A27: 45962 | B27: 2377655 | C27: 1241 | D27: 188.26 | E27: =D27-$P$1 -> 187.60198 | F27: 24 | G27: =D27/F27 -> 7.8441667 | H27: =E27*$K$1 -> 26.495819 | I27: 1
A28: 45962 | B28: 2377658 | C28: 0 | E28: =D28-$P$1 -> -0.65801677 | F28: 29 | G28: =D28/F28 -> 0 | H28: =E28*$K$1 -> -0.092934485 | I28: 1
A29: 45962 | B29: 2378193 | C29: 0 | E29: =D29-$P$1 -> -0.65801677 | F29: 3 | G29: =D29/F29 -> 0 | H29: =E29*$K$1 -> -0.092934485 | I29: 1
A30: 45962 | B30: 2378205 | C30: 2820 | D30: 576.56 | E30: =D30-$P$1 -> 575.90198 | F30: 19 | G30: =D30/F30 -> 30.345263 | H30: =E30*$K$1 -> 81.337066 | I30: 1
A31: 45962 | B31: 2378206 | C31: 3675 | D31: 677.81 | E31: =D31-$P$1 -> 677.15198 | F31: 30 | G31: =D31/F31 -> 22.593667 | H31: =E31*$K$1 -> 95.637031 | I31: 1
A32: 45962 | B32: 2378210 | C32: 319 | D32: -14.07 | E32: =D32-$P$1 -> -14.728017 | F32: 30 | G32: =D32/F32 -> -0.469 | H32: =E32*$K$1 -> -2.0800999 | I32: 1
A33: 45962 | B33: 2378215 | C33: 196 | D33: 4.43 | E33: =D33-$P$1 -> 3.7719832 | F33: 5 | G33: =D33/F33 -> 0.886 | H33: =E33*$K$1 -> 0.5327331 | I33: 1
A34: 45962 | B34: 2378216 | C34: 6754 | D34: 1083.95 | E34: =D34-$P$1 -> 1083.292 | F34: 30 | G34: =D34/F34 -> 36.131667 | H34: =E34*$K$1 -> 152.9979 | I34: 1
A35: 45962 | B35: 2378244 | C35: 0 | E35: =D35-$P$1 -> -0.65801677 | F35: 30 | G35: =D35/F35 -> 0 | H35: =E35*$K$1 -> -0.092934485 | I35: 1
A36: 45962 | B36: 2378248 | C36: 6549 | D36: 702.3 | E36: =D36-$P$1 -> 701.64198 | F36: 30 | G36: =D36/F36 -> 23.41 | H36: =E36*$K$1 -> 99.095857 | I36: 1
A37: 45962 | B37: 2378249 | C37: 640 | D37: 102.76 | E37: =D37-$P$1 -> 102.10198 | F37: 10 | G37: =D37/F37 -> 10.276 | H37: =E37*$K$1 -> 14.420294 | I37: 1
A38: 45962 | B38: 2378252 | C38: 1068 | D38: 173.17 | E38: =D38-$P$1 -> 172.51198 | F38: 30 | G38: =D38/F38 -> 5.7723333 | H38: =E38*$K$1 -> 24.364595 | I38: 1
A39: 45962 | B39: 2378253 | C39: 21266 | D39: 2005.47 | E39: =D39-$P$1 -> 2004.812 | F39: 22 | G39: =D39/F39 -> 91.157727 | H39: =E39*$K$1 -> 283.14805 | I39: 1
A40: 45962 | B40: 2378254 | C40: 2326 | D40: 392.98 | E40: =D40-$P$1 -> 392.32198 | F40: 30 | G40: =D40/F40 -> 13.099333 | H40: =E40*$K$1 -> 55.409289 | I40: 1
...

Sheet Fee Initial Contract
A1: Sum of Daily NGR of all VLTs for a month period (invoice period): | F1: =L1*0.7 -> 5848405 | K1: GGR | L1: ='Asset Data_Initial Contract'!E5731 -> 8354864.3
A2: Sum of operational days (reported days) of all VLTs for a month period: | F2: ='Asset Data_Initial Contract'!F5731 -> 164345 | K2: WPUPD | L2: =F3/0.7 -> 50.83735
A3: Average NGR per day per VLT for a month period : | F3: =F1/F2 -> 35.586145 | G3: NWPUPD
A5: OPERATING FEE CALCULATION
A6: Scale | C6: % Commision | D6: Avr/NGR/month | E6: OP days | F6: Fee
D7: =F3 -> 35.586145
A8: 0 | B8: 28.99 | C8: 0.217 | D8: =MIN(D7,B8) -> 28.99 | E8: =F2 -> 164345 | F8: =D8*E8*C8 -> 1033866.5
A9: 29 | B9: 34.99 | C9: 0.139 | D9: =MIN((D7-D8),(B9-B8)) -> 6 | E9: =F2 -> 164345 | F9: =D9*E9*C9 -> 137063.73
A10: 35 | B10: 42.99 | C10: 0.0925 | D10: =MIN((D7-D8-D9),(B10-B9)) -> 0.59614524 | E10: =F2 -> 164345 | F10: =D10*E10*C10 -> 9062.5478
A11: 43 | B11: 48.99 | C11: 0.065 | D11: =MIN((D7-D8-D9-D10),(B11-B10)) -> 0 | E11: =F2 -> 164345 | F11: =D11*E11*C11 -> 0
A12: 49 | C12: 0.055 | D12: =D7-(D8+D9+D10+D11) -> 0 | E12: =F2 -> 164345 | F12: =D12*E12*C12 -> 0
D13: =SUM(D8:D12) -> 35.586145 | F13: =SUM(F8:F12) -> 1179992.7
F18: =F13/L1 -> 0.14123422 | G18: Revenue Share

Sheet Asset Data_New Contract
A1: Month of Period Start | B1: Machine ID:SERIAL # | C1: Sum of Coin In | D1: Sum of Net Win | E1: Net Win_2 (Players Reward deducted) | F1: EGM Day Count | G1: WPUPD | H1: Fee/Revenue | I1: Upfront fee € | J1: Total Revenue | K1: Distinct Ser# Count | M1: Revenue Share | N1: ='Fee New Contract'!E13 -> 0.039998 | Q1: Total | R1: Per Machine
A2: 45962 | B2: EU0000700 | C2: 3912 | D2: 337.94 | E2: =D2-$R$2 -> 337.2727 | F2: 23 | G2: =D2/F2 -> 14.693043 | H2: =E2*$N$1 -> 13.490233 | I2: =$S$5 -> 61.15774 | J2: =H2+I2 -> 74.647973 | K2: 1 | P2: Players Reward scheme | Q2: 715.34946 | R2: =Q2/K1074 -> 0.6673036
A3: 45962 | B3: EU0000701 | C3: 3544 | D3: 474.57 | E3: =D3-$R$2 -> 473.9027 | F3: 15 | G3: =D3/F3 -> 31.638 | H3: =E3*$N$1 -> 18.95516 | I3: =$S$5 -> 61.15774 | J3: =H3+I3 -> 80.1129 | K3: 1
A4: 45962 | B4: EU0000703 | C4: 43203 | D4: 3664.62 | E4: =D4-$R$2 -> 3663.9527 | F4: 30 | G4: =D4/F4 -> 122.154 | H4: =E4*$N$1 -> 146.55078 | I4: =$S$5 -> 61.15774 | J4: =H4+I4 -> 207.70852 | K4: 1 | P4: Upfront fee $ | Q4: Exchange Rate | R4: Upfront fee € | S4: Upfront Fee per Machine
A5: 45962 | B5: EU0000706 | C5: 436442 | D5: 25829.99 | E5: =D5-$R$2 -> 25829.323 | F5: 1 | G5: =D5/F5 -> 25829.99 | H5: =E5*$N$1 -> 1033.1212 | I5: =$S$5 -> 61.15774 | J5: =H5+I5 -> 1094.279 | K5: 1 | P5: 66194 | Q5: 1.1087 | R5: 73389.288 | S5: 61.15774
A6: 45962 | B6: EU0000707 | C6: 8675 | D6: 96.36 | E6: =D6-$R$2 -> 95.692696 | F6: 30 | G6: =D6/F6 -> 3.212 | H6: =E6*$N$1 -> 3.8275165 | I6: =$S$5 -> 61.15774 | J6: =H6+I6 -> 64.985256 | K6: 1
A7: 45962 | B7: EU0000708 | C7: 27776 | D7: 336.98 | E7: =D7-$R$2 -> 336.3127 | F7: 30 | G7: =D7/F7 -> 11.232667 | H7: =E7*$N$1 -> 13.451835 | I7: =$S$5 -> 61.15774 | J7: =H7+I7 -> 74.609575 | K7: 1
A8: 45962 | B8: EU0000710 | C8: 938 | D8: 109.05 | E8: =D8-$R$2 -> 108.3827 | F8: 30 | G8: =D8/F8 -> 3.635 | H8: =E8*$N$1 -> 4.3350911 | I8: =$S$5 -> 61.15774 | J8: =H8+I8 -> 65.492831 | K8: 1
A9: 45962 | B9: EU0000718 | C9: 8643 | D9: 930.46 | E9: =D9-$R$2 -> 929.7927 | F9: 30 | G9: =D9/F9 -> 31.015333 | H9: =E9*$N$1 -> 37.189848 | I9: =$S$5 -> 61.15774 | J9: =H9+I9 -> 98.347588 | K9: 1
A10: 45962 | B10: EU0000724 | C10: 16196 | D10: 1583.68 | E10: =D10-$R$2 -> 1583.0127 | F10: 30 | G10: =D10/F10 -> 52.789333 | H10: =E10*$N$1 -> 63.317342 | I10: =$S$5 -> 61.15774 | J10: =H10+I10 -> 124.47508 | K10: 1
A11: 45962 | B11: EU0000726 | C11: 3822 | D11: -757.26 | E11: =D11-$R$2 -> -757.9273 | F11: 4 | G11: =D11/F11 -> -189.315 | H11: =E11*$N$1 -> -30.315576 | I11: =$S$5 -> 61.15774 | J11: =H11+I11 -> 30.842164 | K11: 1
A12: 45962 | B12: EU0000734 | C12: 6633 | D12: 489.84 | E12: =D12-$R$2 -> 489.1727 | F12: 30 | G12: =D12/F12 -> 16.328 | H12: =E12*$N$1 -> 19.56593 | I12: =$S$5 -> 61.15774 | J12: =H12+I12 -> 80.723669 | K12: 1
A13: 45962 | B13: EU0000738 | C13: 411 | D13: 58.8 | E13: =D13-$R$2 -> 58.132696 | F13: 11 | G13: =D13/F13 -> 5.3454545 | H13: =E13*$N$1 -> 2.3251916 | I13: =$S$5 -> 61.15774 | J13: =H13+I13 -> 63.482931 | K13: 1
A14: 45962 | B14: EU0000757 | C14: 7323 | D14: -953.59 | E14: =D14-$R$2 -> -954.2573 | F14: 30 | G14: =D14/F14 -> -31.786333 | H14: =E14*$N$1 -> -38.168384 | I14: =$S$5 -> 61.15774 | J14: =H14+I14 -> 22.989356 | K14: 1
A15: 45962 | B15: EU0000758 | C15: 35330 | D15: 3432.34 | E15: =D15-$R$2 -> 3431.6727 | F15: 24 | G15: =D15/F15 -> 143.01417 | H15: =E15*$N$1 -> 137.26004 | I15: =$S$5 -> 61.15774 | J15: =H15+I15 -> 198.41778 | K15: 1
A16: 45962 | B16: EU0000759 | C16: 966 | D16: 146.51 | E16: =D16-$R$2 -> 145.8427 | F16: 4 | G16: =D16/F16 -> 36.6275 | H16: =E16*$N$1 -> 5.8334162 | I16: =$S$5 -> 61.15774 | J16: =H16+I16 -> 66.991156 | K16: 1
A17: 45962 | B17: EU0000760 | C17: 4815 | D17: -97.57 | E17: =D17-$R$2 -> -98.237304 | F17: 30 | G17: =D17/F17 -> -3.2523333 | H17: =E17*$N$1 -> -3.9292957 | I17: =$S$5 -> 61.15774 | J17: =H17+I17 -> 57.228444 | K17: 1
... A61: 45962 | B61: EU0000809 | C61: 16723 | D61: 136.32 | E61: =D61-$R$2 -> 135.6527 | F61: 30 | G61: =D61/F61 -> 4.544 | H61: =E61*$N$1 -> 5.4258366 | I61: =$S$5 -> 61.15774 | J61: =H61+I61 -> 66.583576 | K61: 1
A62: 45962 | B62: EU0000810 | C62: 0 | E62: =D62-$R$2 -> -0.6673036 | F62: 2 | G62: =D62/F62 -> 0 | H62: =E62*$N$1 -> -0.026690809 | I62: =$S$5 -> 61.15774 | J62: =H62+I62 -> 61.131049 | K62: 1
A63: 45962 | B63: EU0000811 | C63: 18215 | D63: 835.53 | E63: =D63-$R$2 -> 834.8627 | F63: 30 | G63: =D63/F63 -> 27.851 | H63: =E63*$N$1 -> 33.392838 | I63: =$S$5 -> 61.15774 | J63: =H63+I63 -> 94.550578 | K63: 1
A64: 45962 | B64: EU0000812 | C64: 24344 | D64: 2184.39 | E64: =D64-$R$2 -> 2183.7227 | F64: 30 | G64: =D64/F64 -> 72.813 | H64: =E64*$N$1 -> 87.34454 | I64: =$S$5 -> 61.15774 | J64: =H64+I64 -> 148.50228 | K64: 1
A65: 45962 | B65: EU0000813 | C65: 287 | D65: 54.33 | E65: =D65-$R$2 -> 53.662696 | F65: 14 | G65: =D65/F65 -> 3.8807143 | H65: =E65*$N$1 -> 2.1464005 | I65: =$S$5 -> 61.15774 | J65: =H65+I65 -> 63.30414 | K65: 1
A66: 45962 | B66: EU0000814 | C66: 3899 | D66: -453.86 | E66: =D66-$R$2 -> -454.5273 | F66: 3 | G66: =D66/F66 -> -151.28667 | H66: =E66*$N$1 -> -18.180183 | I66: =$S$5 -> 61.15774 | J66: =H66+I66 -> 42.977557 | K66: 1
A67: 45962 | B67: EU0000815 | C67: 4036 | D67: 453.06 | E67: =D67-$R$2 -> 452.3927 | F67: 27 | G67: =D67/F67 -> 16.78 | H67: =E67*$N$1 -> 18.094803 | I67: =$S$5 -> 61.15774 | J67: =H67+I67 -> 79.252543 | K67: 1
A68: 45962 | B68: EU0000816 | C68: 9507 | D68: 534.95 | E68: =D68-$R$2 -> 534.2827 | F68: 30 | G68: =D68/F68 -> 17.831667 | H68: =E68*$N$1 -> 21.370239 | I68: =$S$5 -> 61.15774 | J68: =H68+I68 -> 82.527979 | K68: 1
A69: 45962 | B69: EU0000817 | C69: 8002 | D69: 317.31 | E69: =D69-$R$2 -> 316.6427 | F69: 30 | G69: =D69/F69 -> 10.577 | H69: =E69*$N$1 -> 12.665075 | I69: =$S$5 -> 61.15774 | J69: =H69+I69 -> 73.822814 | K69: 1
A70: 45962 | B70: EU0000818 | C70: 13872 | D70: 2339.44 | E70: =D70-$R$2 -> 2338.7727 | F70: 30 | G70: =D70/F70 -> 77.981333 | H70: =E70*$N$1 -> 93.54623 | I70: =$S$5 -> 61.15774 | J70: =H70+I70 -> 154.70397 | K70: 1
A71: 45962 | B71: EU0000820 | C71: 10910 | D71: 1762.05 | E71: =D71-$R$2 -> 1761.3827 | F71: 28 | G71: =D71/F71 -> 62.930357 | H71: =E71*$N$1 -> 70.451785 | I71: =$S$5 -> 61.15774 | J71: =H71+I71 -> 131.60952 | K71: 1
A72: 45962 | B72: EU0000822 | C72: 3645 | D72: -189.64 | E72: =D72-$R$2 -> -190.3073 | F72: 13 | G72: =D72/F72 -> -14.587692 | H72: =E72*$N$1 -> -7.6119115 | I72: =$S$5 -> 61.15774 | J72: =H72+I72 -> 53.545828 | K72: 1
A73: 45962 | B73: EU0000823 | C73: 25240 | D73: 1610.62 | E73: =D73-$R$2 -> 1609.9527 | F73: 30 | G73: =D73/F73 -> 53.687333 | H73: =E73*$N$1 -> 64.394888 | I73: =$S$5 -> 61.15774 | J73: =H73+I73 -> 125.55263 | K73: 1
A74: 45962 | B74: EU0000824 | C74: 9504 | D74: 932.54 | E74: =D74-$R$2 -> 931.8727 | F74: 30 | G74: =D74/F74 -> 31.084667 | H74: =E74*$N$1 -> 37.273044 | I74: =$S$5 -> 61.15774 | J74: =H74+I74 -> 98.430784 | K74: 1
... A78: 45962 | B78: EU0000829 | C78: 10084 | D78: 1757.16 | E78: =D78-$R$2 -> 1756.4927 | F78: 30 | G78: =D78/F78 -> 58.572 | H78: =E78*$N$1 -> 70.256195 | I78: =$S$5 -> 61.15774 | J78: =H78+I78 -> 131.41393 | K78: 1
A79: 45962 | B79: EU0000830 | C79: 0 | E79: =D79-$R$2 -> -0.6673036 | F79: 4 | G79: =D79/F79 -> 0 | H79: =E79*$N$1 -> -0.026690809 | I79: =$S$5 -> 61.15774 | J79: =H79+I79 -> 61.131049 | K79: 1
A80: 45962 | B80: EU0000831 | C80: 38875 | D80: 2328.86 | E80: =D80-$R$2 -> 2328.1927 | F80: 30 | G80: =D80/F80 -> 77.628667 | H80: =E80*$N$1 -> 93.123051 | I80: =$S$5 -> 61.15774 | J80: =H80+I80 -> 154.28079 | K80: 1
A81: 45962 | B81: EU0000832 | C81: 7714 | D81: 1008.6 | E81: =D81-$R$2 -> 1007.9327 | F81: 30 | G81: =D81/F81 -> 33.62 | H81: =E81*$N$1 -> 40.315292 | I81: =$S$5 -> 61.15774 | J81: =H81+I81 -> 101.47303 | K81: 1
A82: 45962 | B82: EU0000833 | C82: 215 | D82: 65 | E82: =D82-$R$2 -> 64.332696 | F82: 14 | G82: =D82/F82 -> 4.6428571 | H82: =E82*$N$1 -> 2.5731792 | I82: =$S$5 -> 61.15774 | J82: =H82+I82 -> 63.730919 | K82: 1
A83: 45962 | B83: EU0000834 | C83: 40249 | D83: 577.06 | E83: =D83-$R$2 -> 576.3927 | F83: 30 | G83: =D83/F83 -> 19.235333 | H83: =E83*$N$1 -> 23.054555 | I83: =$S$5 -> 61.15774 | J83: =H83+I83 -> 84.212295 | K83: 1
A84: 45962 | B84: EU0000835 | C84: 863 | D84: 26.83 | E84: =D84-$R$2 -> 26.162696 | F84: 5 | G84: =D84/F84 -> 5.366 | H84: =E84*$N$1 -> 1.0464555 | I84: =$S$5 -> 61.15774 | J84: =H84+I84 -> 62.204195 | K84: 1
A85: 45962 | B85: EU0000837 | C85: 212 | D85: 104.09 | E85: =D85-$R$2 -> 103.4227 | F85: 3 | G85: =D85/F85 -> 34.696667 | H85: =E85*$N$1 -> 4.136701 | I85: =$S$5 -> 61.15774 | J85: =H85+I85 -> 65.294441 | K85: 1
A86: 45962 | B86: EU0000838 | C86: 7474 | D86: 1107.75 | E86: =D86-$R$2 -> 1107.0827 | F86: 10 | G86: =D86/F86 -> 110.775 | H86: =E86*$N$1 -> 44.281094 | I86: =$S$5 -> 61.15774 | J86: =H86+I86 -> 105.43883 | K86: 1
...

Sheet Fee New Contract
I2: VLT Days | J2: ='Asset Data_New Contract'!F1074 -> 29369
A3: OPERATING FEE CALCULATION | I3: GGR | J3: ='Asset Data_New Contract'!E1074 -> 1142398
A4: Scale | C4: % Commision | D4: Avr/NGR/month | E4: OP days | F4: Fee | I4: NGR | J4: =J3*70% -> 799678.61
D5: =J6 -> 27.228663 | I5: WPUPD | J5: =J3/J2 -> 38.898091
A6: 0 | B6: 28 | C6: 0.05714 | D6: =MIN(D5,B6) -> 27.228663 | E6: =J2 -> 29369 | F6: =D6*E6*C6 -> 45693.636 | I6: NWPUPD | J6: =J4/J2 -> 27.228663
A7: 28.01 | C7: 0.04286 | D7: =D5-D6 -> 0 | E7: =J2 -> 29369 | F7: =D7*E7*C7 -> 0
D8: =SUM(D6:D7) -> 27.228663 | F8: =SUM(F6:F7) -> 45693.636
D13: Revenue Share | E13: =F8/J3 -> 0.039998

Sheet OPAP's data_Initial Contract
A1: Serial No | B1: GGR | C1: GGR2 (Players Reward scheme deducted) | D1: Fee/Revenue | E1: Revenue Share | H1: Total | I1: Per Machine | K1: OPAP's Reporting Days
A2: MX0016251 | B2: 868.577 | C2: =B2-$I$2 -> 867.92771 | D2: =C2*$E$2 -> 123.58147 | E2: ='Fee Initial Contract OPAP D'!F18 -> 0.14238683 | G2: Players Reward scheme | H2: 3769.7781 | I2: =H2/5806 -> 0.64929006 | K2: 165227
A3: MX0017700 | B3: 657.263 | C3: =B3-$I$2 -> 656.61371 | D3: =C3*$E$2 -> 93.493143
A4: 2411994 | B4: 394.506 | C4: =B4-$I$2 -> 393.85671 | D4: =C4*$E$2 -> 56.080007
A5: EU0006954 | B5: -12.46 | C5: =B5-$I$2 -> -13.10929 | D5: =C5*$E$2 -> -1.8665902
A6: MX0010390 | B6: 388.007 | C6: =B6-$I$2 -> 387.35771 | D6: =C6*$E$2 -> 55.154635
A7: MX0010405 | B7: 353.377 | C7: =B7-$I$2 -> 352.72771 | D7: =C7*$E$2 -> 50.223779
A8: MX0016609 | B8: -1215.923 | C8: =B8-$I$2 -> -1216.5723 | D8: =C8*$E$2 -> -173.22387
A9: MX0018741 | B9: 1131.867 | C9: =B9-$I$2 -> 1131.2177 | D9: =C9*$E$2 -> 161.0705
A10: MX0016601 | B10: 1169.468 | C10: =B10-$I$2 -> 1168.8187 | D10: =C10*$E$2 -> 166.42439
A11: MX0017657 | B11: -49.864 | C11: =B11-$I$2 -> -50.51329 | D11: =C11*$E$2 -> -7.1924271
A12: MX0016606 | B12: 2017.874 | C12: =B12-$I$2 -> 2017.2247 | D12: =C12*$E$2 -> 287.22623
A13: 2411944 | B13: 232.082 | C13: =B13-$I$2 -> 231.43271 | D13: =C13*$E$2 -> 32.952969
A14: MX0007521 | B14: 33.532 | C14: =B14-$I$2 -> 32.88271 | D14: =C14*$E$2 -> 4.6820647
... A5807: MX0010389 | B5807: 1512.27 | C5807: =B5807-$I$2 -> 1511.6207 | D5807: =C5807*$E$2 -> 215.23488
B5808: =SUM(B2:B5807) -> 8278769.3 | C5808: =SUM(C2:C5807) -> 8274999.5 | D5808: =SUM(D2:D5807) -> 1178250.9

Sheet Fee Initial Contract OPAP D
A1: Sum of Daily NGR of all VLTs for a month period (invoice period): | F1: =L1*0.7 -> 5792499.7 | K1: GGR | L1: ='OPAP''s data_Initial Contract'!C5808 -> 8274999.5
A2: Sum of operational days (reported days) of all VLTs for a month period: | F2: ='OPAP''s data_Initial Contract'!K2 -> 165227 | K2: WPUPD | L2: =F3/0.7 -> 50.082611
A3: Average NGR per day per VLT for a month period : | F3: =F1/F2 -> 35.057828 | G3: NWPUPD
A5: OPERATING FEE CALCULATION
A6: Scale | C6: % Commision | D6: Avr/NGR/month | E6: OP days | F6: Fee
D7: =F3 -> 35.057828
A8: 0 | B8: 28.99 | C8: 0.217 | D8: =MIN(D7,B8) -> 28.99 | E8: =F2 -> 165227 | F8: =D8*E8*C8 -> 1039415
A9: 29 | B9: 34.99 | C9: 0.139 | D9: =MIN((D7-D8),(B9-B8)) -> 6 | E9: =F2 -> 165227 | F9: =D9*E9*C9 -> 137799.32
A10: 35 | B10: 42.99 | C10: 0.0925 | D10: =MIN((D7-D8-D9),(B10-B9)) -> 0.067827612 | E10: =F2 -> 165227 | F10: =D10*E10*C10 -> 1036.6431
A11: 43 | B11: 48.99 | C11: 0.065 | D11: =MIN((D7-D8-D9-D10),(B11-B10)) -> 0 | E11: =F2 -> 165227 | F11: =D11*E11*C11 -> 0
A12: 49 | C12: 0.055 | D12: =D7-(D8+D9+D10+D11) -> 0 | E12: =F2 -> 165227 | F12: =D12*E12*C12 -> 0
D13: =SUM(D8:D12) -> 35.057828 | F13: =SUM(F8:F12) -> 1178250.9
F18: =F13/L1 -> 0.14238683 | G18: Revenue Share

Sheet OPAP's data_New Contract
A1: Serial No | B1: GGR | C1: GGR2 (Players Reward scheme deducted) | D1: Fee/Revenue | E1: Upfront Fee | F1: Total Revenue | G1: Revenue Share | J1: Total | K1: Per Machine | N1: OPAP's Reporting Days
A2: MX0004893 | B2: -810.188 | C2: =B2-$K$2 -> -810.84489 | D2: =C2*$G$2 -> -32.433877 | E2: =$L$5 -> 61.15774 | F2: =D2+E2 -> 28.723863 | G2: ='Fee New Contract OPAP Data'!E13 -> 0.0400001 | I2: Players Reward scheme | J2: 715.34946 | K2: =J2/1089 -> 0.65688656 | N2: 29721
A3: EU0000912 | B3: -369.423 | C3: =B3-$K$2 -> -370.07989 | D3: =C3*$G$2 -> -14.803232 | E3: =$L$5 -> 61.15774 | F3: =D3+E3 -> 46.354507
A4: MX0003067 | B4: 689.254 | C4: =B4-$K$2 -> 688.59711 | D4: =C4*$G$2 -> 27.543953 | E4: =$L$5 -> 61.15774 | F4: =D4+E4 -> 88.701693 | I4: Upfront fee $ | J4: Exchange Rate | K4: Upfront fee € | L4: Upfront Fee per Machine
A5: EU0000803 | B5: 2109.543 | C5: =B5-$K$2 -> 2108.8861 | D5: =C5*$G$2 -> 84.355655 | E5: =$L$5 -> 61.15774 | F5: =D5+E5 -> 145.5134 | I5: 66194 | J5: 1.1087 | K5: =I5*J5 -> 73389.288 | L5: =K5/1200 -> 61.15774
A6: MX0002418 | B6: 143.221 | C6: =B6-$K$2 -> 142.56411 | D6: =C6*$G$2 -> 5.7025788 | E6: =$L$5 -> 61.15774 | F6: =D6+E6 -> 66.860319
A7: MX0002433 | B7: 553.655 | C7: =B7-$K$2 -> 552.99811 | D7: =C7*$G$2 -> 22.11998 | E7: =$L$5 -> 61.15774 | F7: =D7+E7 -> 83.27772
A8: MX0004021 | B8: 91.813 | C8: =B8-$K$2 -> 91.156113 | D8: =C8*$G$2 -> 3.6462537 | E8: =$L$5 -> 61.15774 | F8: =D8+E8 -> 64.803993
A9: MX0003001 | B9: -681.752 | C9: =B9-$K$2 -> -682.40889 | D9: =C9*$G$2 -> -27.296424 | E9: =$L$5 -> 61.15774 | F9: =D9+E9 -> 33.861316
A10: MX0004300 | B10: -300.184 | C10: =B10-$K$2 -> -300.84089 | D10: =C10*$G$2 -> -12.033666 | E10: =$L$5 -> 61.15774 | F10: =D10+E10 -> 49.124074
A11: MX0004841 | B11: 805.202 | C11: =B11-$K$2 -> 804.54511 | D11: =C11*$G$2 -> 32.181885 | E11: =$L$5 -> 61.15774 | F11: =D11+E11 -> 93.339625
A12: MX0004901 | B12: 970.04 | C12: =B12-$K$2 -> 969.38311 | D12: =C12*$G$2 -> 38.775421 | E12: =$L$5 -> 61.15774 | F12: =D12+E12 -> 99.933161
A13: MX0004976 | B13: 12.005 | C13: =B13-$K$2 -> 11.348113 | D13: =C13*$G$2 -> 0.45392567 | E13: =$L$5 -> 61.15774 | F13: =D13+E13 -> 61.611666
A14: MX0003929 | B14: -187.165 | C14: =B14-$K$2 -> -187.82189 | D14: =C14*$G$2 -> -7.5128942 | E14: =$L$5 -> 61.15774 | F14: =D14+E14 -> 53.644846
A15: MX0004977 | B15: 118.937 | C15: =B15-$K$2 -> 118.28011 | D15: =C15*$G$2 -> 4.7312164 | E15: =$L$5 -> 61.15774 | F15: =D15+E15 -> 65.888956
A16: MX0002358 | B16: 301.183 | C16: =B16-$K$2 -> 300.52611 | D16: =C16*$G$2 -> 12.021075 | E16: =$L$5 -> 61.15774 | F16: =D16+E16 -> 73.178814
A17: MX0004028 | B17: -95.048 | C17: =B17-$K$2 -> -95.704887 | D17: =C17*$G$2 -> -3.828205 | E17: =$L$5 -> 61.15774 | F17: =D17+E17 -> 57.329535
... A1090: MX0003658 | B1090: -1082.582 | C1090: =B1090-$K$2 -> -1083.2389 | D1090: =C1090*$G$2 -> -43.329664 | E1090: =$L$5 -> 61.15774 | F1090: =D1090+E1090 -> 17.828076
B1091: =SUM(B2:B1090) -> 1113917.5 | C1091: =SUM(C2:C1090) -> 1113202.2 | D1091: =SUM(D2:D1090) -> 44528.198 | E1091: =SUM(E2:E1090) -> 66600.779 | F1091: =SUM(F2:F1090) -> 111128.98

Sheet Fee New Contract OPAP Data
I2: VLT Days | J2: ='OPAP''s data_New Contract'!N2 -> 29721
A3: OPERATING FEE CALCULATION | I3: GGR | J3: ='OPAP''s data_New Contract'!C1091 -> 1113202.2
A4: Scale | C4: % Commision | D4: Avr/NGR/month | E4: OP days | F4: Fee | I4: NGR | J4: =J3*70% -> 779241.51
D5: =J6 -> 26.218549 | I5: WPUPD | J5: =J3/J2 -> 37.455071
A6: 0 | B6: 28 | C6: 0.057143 | D6: =MIN(D5,B6) -> 26.218549 | E6: =J2 -> 29721 | F6: =D6*E6*C6 -> 44528.198 | I6: NWPUPD | J6: =J4/J2 -> 26.218549
A7: 28.01 | C7: 0.04286 | D7: =D5-D6 -> 0 | E7: =J2 -> 29721 | F7: =D7*E7*C7 -> 0
D8: =SUM(D6:D7) -> 26.218549 | F8: =SUM(F6:F7) -> 44528.198
D13: Revenue Share | E13: =F8/J3 -> 0.0400001
