Workbook

Sheet For Garrett
AA2: 2019 | AM2: 2020 | AY2: 2021 | BK2: 2022 | BW2: 2023 | CI2: 2024 | CU2: 2025
C3: Jan | D3: Feb | E3: Mar | F3: Apr | G3: May | H3: Jun | I3: Jul | J3: Aug | K3: Sep | L3: Oct | M3: Nov | N3: Dec | O3: Jan | P3: Feb | Q3: Mar | R3: Apr | S3: May | T3: Jun | U3: Jul | V3: Aug | W3: Sep | X3: Oct | Y3: Nov | Z3: Dec | AA3: Jan | AB3: Feb | AC3: Mar | AD3: Apr | AE3: May | AF3: Jun | AG3: Jul | AH3: Aug | AI3: Sep | AJ3: Oct | AK3: Nov | AL3: Dec | AM3: Jan | AN3: Feb | AO3: Mar | AP3: Apr | AQ3: May | AR3: June | AS3: July | AT3: August | AU3: September | AV3: October | AW3: November | AX3: December | AY3: January | AZ3: February | BA3: March | BB3: April | BC3: May | BD3: June | BE3: July | BF3: August | BG3: September | BH3: October | BI3: November | BJ3: December | BK3: January | BL3: February | BM3: March | BN3: April | BO3: May | BP3: June | BQ3: July | BR3: August | BS3: September | BT3: October | BU3: November | BV3: December | BW3: January | BX3: February | BY3: March | BZ3: April | CA3: May | CB3: June | CC3: July | CD3: August | CE3: September | CF3: October | CG3: November | CH3: December | CI3: January | CJ3: February | CK3: March | CL3: April | CM3: May | CN3: June | CO3: July | CP3: August | CQ3: September | CR3: October | CS3: November | CT3: December | CU3: January | CV3: February | CW3: March | CX3: April | CY3: May | CZ3: June | DA3: July | DB3: August | DC3: September | DD3: October | DE3: November | DF3: December
B4: Gross Revenue (less Freight) | C4: ='[1]Ad Hoc BPC Data Linked'!D40 -> 5676622.3 | D4: ='[1]Ad Hoc BPC Data Linked'!E40 -> 11789195 | E4: ='[1]Ad Hoc BPC Data Linked'!F40 -> 51980266 | F4: ='[1]Ad Hoc BPC Data Linked'!G40 -> 7298743.2 | G4: ='[1]Ad Hoc BPC Data Linked'!H40 -> 37143606 | H4: ='[1]Ad Hoc BPC Data Linked'!I40 -> 56309810 | I4: ='[1]Ad Hoc BPC Data Linked'!J40 -> 10513426 | J4: ='[1]Ad Hoc BPC Data Linked'!K40 -> 13612303 | ... Z4: ='[1]Ad Hoc BPC Data Linked'!AA40 -> 93737469 | AA4: ='Ad Hoc BPC Data Linked'!B66 -> 10048753 | AB4: ='Ad Hoc BPC Data Linked'!C66 -> 11328311 | AC4: ='Ad Hoc BPC Data Linked'!D66 -> 68344612 | AD4: ='Ad Hoc BPC Data Linked'!E66 -> 11827003 | AE4: ='Ad Hoc BPC Data Linked'!F66 -> 25211087 | AF4: ='Ad Hoc BPC Data Linked'!G66 -> 64404447 | AG4: ='Ad Hoc BPC Data Linked'!H66 -> 14117807 | AH4: ='Ad Hoc BPC Data Linked'!I66 -> 24305344 | ... DF4: ='Ad Hoc BPC Data Linked'!CG66 -> 1.1016403e+08
B5: Discount (Excl. NRV Credit) | C5: ='[1]Ad Hoc BPC Data Linked'!D42*-1 -> 1773623.2 | D5: ='[1]Ad Hoc BPC Data Linked'!E42*-1 -> 2856430.6 | E5: ='[1]Ad Hoc BPC Data Linked'!F42*-1 -> 14591670 | F5: ='[1]Ad Hoc BPC Data Linked'!G42*-1 -> 1566789.2 | G5: ='[1]Ad Hoc BPC Data Linked'!H42*-1 -> 11233139 | H5: ='[1]Ad Hoc BPC Data Linked'!I42*-1 -> 15785340 | I5: ='[1]Ad Hoc BPC Data Linked'!J42*-1 -> 2418393.7 | J5: ='[1]Ad Hoc BPC Data Linked'!K42*-1 -> 4193558.2 | ... Z5: ='[1]Ad Hoc BPC Data Linked'!AA42*-1 -> 31280530 | AA5: ='Ad Hoc BPC Data Linked'!B68*-1 -> 3173399.1 | AB5: ='Ad Hoc BPC Data Linked'!C68*-1 -> 3863831.4 | AC5: ='Ad Hoc BPC Data Linked'!D68*-1 -> 19891050 | AD5: ='Ad Hoc BPC Data Linked'!E68*-1 -> 2789201.9 | AE5: ='Ad Hoc BPC Data Linked'!F68*-1 -> 7664037.1 | AF5: ='Ad Hoc BPC Data Linked'!G68*-1 -> 18671830 | AG5: ='Ad Hoc BPC Data Linked'!H68*-1 -> 3985348.8 | AH5: ='Ad Hoc BPC Data Linked'!I68*-1 -> 7156847.5 | ... DF5: ='Ad Hoc BPC Data Linked'!CG68*-1 -> 22943562
B6: Net Revenue | C6: =C4-C5 -> 3902999.1 | D6: =D4-D5 -> 8932763.9 | E6: =E4-E5 -> 37388596 | F6: =F4-F5 -> 5731954 | G6: =G4-G5 -> 25910467 | H6: =H4-H5 -> 40524470 | I6: =I4-I5 -> 8095032.6 | J6: =J4-J5 -> 9418745 | ... DF6: =DF4-DF5 -> 87220467
B7: Cost | C7: ='[1]Ad Hoc BPC Data Linked'!D62 -> 0 | D7: ='[1]Ad Hoc BPC Data Linked'!E62 -> 0 | E7: ='[1]Ad Hoc BPC Data Linked'!F62 -> 0 | F7: ='[1]Ad Hoc BPC Data Linked'!G62 -> 0 | G7: ='[1]Ad Hoc BPC Data Linked'!H62 -> 0 | H7: ='[1]Ad Hoc BPC Data Linked'!I62 -> 0 | I7: ='[1]Ad Hoc BPC Data Linked'!J62 -> 0 | J7: ='[1]Ad Hoc BPC Data Linked'!K62 -> 0 | ... Z7: ='[1]Ad Hoc BPC Data Linked'!AA62 -> 0 | AA7: 0 | AB7: 0 | AC7: 0 | AD7: 0 | AE7: 0 | AF7: 0 | AG7: 0 | AH7: 0 | AI7: 0 | AJ7: 0 | AK7: 0 | AL7: 0 | AM7: 0 | AN7: 0 | AO7: 0 | AP7: 0 | AQ7: 0 | AR7: 0 | AS7: 0 | AT7: 0 | AU7: 0 | AV7: 0 | AW7: 0 | AX7: 0 | AY7: 0 | AZ7: 0 | BA7: 0 | BB7: 0 | BC7: 0 | BD7: 0 | BE7: 0 | BF7: 0 | BG7: 0 | BH7: 0 | BI7: 0 | BJ7: 0 | BK7: 0 | BL7: 0 | BM7: 0 | BN7: 0 | BO7: 0 | BP7: 0 | BQ7: 0 | BR7: 0 | BS7: 0 | BT7: 0 | BU7: 1 | BV7: 0 | BW7: 1 | BX7: 0 | BY7: 1 | BZ7: 0 | CA7: 0 | CB7: 0 | CC7: 0 | CD7: 0 | CE7: 0 | CF7: 0 | CG7: 0 | CH7: 1 | CI7: 0 | CJ7: 0 | CK7: 0 | CL7: 0 | CM7: 0 | CN7: 0 | CO7: 0 | CP7: 0 | CQ7: 0 | CR7: 0 | CS7: 0 | CT7: 0 | CU7: 0 | CV7: 0 | CW7: 0 | CX7: 0 | CY7: 0 | CZ7: 0 | DA7: 0 | DB7: 0 | DC7: 0 | DD7: 0 | DE7: 1 | DF7: 2
B8: Profit (Excl. Freight & NRV) | C8: =C6-C7 -> 3902999.1 | D8: =D6-D7 -> 8932763.9 | E8: =E6-E7 -> 37388596 | F8: =F6-F7 -> 5731954 | G8: =G6-G7 -> 25910467 | H8: =H6-H7 -> 40524470 | I8: =I6-I7 -> 8095032.6 | J8: =J6-J7 -> 9418745 | ... DF8: =DF6-DF7 -> 87220465
B12: PASTE VALUES
B13: Gross Revenue (less Freight) | C13: 5676622.3 | D13: 11789195 | E13: 51980266 | F13: 7298743.2 | G13: 37143606 | H13: 56309810 | I13: 10513426 | J13: 13612303 | K13: 41185607 | L13: 9079572.8 | M13: 22318596 | N13: 75433100 | O13: 8364445.3 | P13: 21320936 | Q13: 45179754 | R13: 9911853.1 | S13: 21474255 | T13: 56084541 | U13: 11561194 | V13: 15987899 | W13: 47311072 | X13: 22571070 | Y13: 24004706 | Z13: 93737469 | AA13: 10048753 | AB13: 11328311 | AC13: 68344612 | AD13: 11827003 | AE13: 25211087 | AF13: 64404447 | AG13: 14117807 | AH13: 24305344 | AI13: 64195086 | AJ13: 8298532.9 | AK13: 31276711 | AL13: 1.2669391e+08 | AM13: 8596085.6 | AN13: 11252087 | AO13: 22438481 | AP13: 1367165 | AQ13: 10407752 | AR13: 45430619 | AS13: 6508584.8 | AT13: 13146441 | AU13: 32252240 | AV13: 11936089 | AW13: 10369035 | AX13: 43185999 | AY13: 10801777 | AZ13: 14552203 | BA13: 28187531 | BB13: 14923401 | BC13: 21342926 | BD13: 42803840 | BE13: 20828703 | BF13: 19216483 | BG13: 35952526 | BH13: 11024401 | BI13: 23297453 | BJ13: 71069429 | BK13: 25711551 | BL13: 23526569 | BM13: 56009432 | BN13: 15742284 | BO13: 20111566 | BP13: 66484679 | BQ13: 15229717 | BR13: 35254582 | BS13: 81935413 | BT13: 20900450 | BU13: 43845537 | BV13: 83947656 | BW13: 23847073 | BX13: 35326768 | BY13: 81128521 | BZ13: 29904053 | CA13: 50811051 | CB13: 60928227 | CC13: 25758905 | CD13: 49592979 | CE13: 59732475 | CF13: 30247371 | CG13: 43248263 | CH13: 68726650 | CI13: 16507840 | CJ13: 28887226 | CK13: 69296917 | CL13: 19630061 | CM13: 25424096 | CN13: 72487666 | CO13: 17828404 | CP13: 33203365 | CQ13: 68146868 | CR13: 24321512 | CS13: 35349292 | CT13: 1.2151461e+08 | CU13: 13883296 | CV13: 28680189 | CW13: 65054350 | CX13: 12367335 | CY13: 25066078 | CZ13: 61550980 | DA13: 18987055 | DB13: 42060689 | DC13: 69495846 | DD13: 32301093 | DE13: 42396059 | DF13: 1.1016403e+08
B14: Discount (Excl. NRV Credit) | C14: 1788581.2 | D14: 2856430.6 | E14: 14605118 | F14: 1551831.2 | G14: 11233139 | H14: 15795728 | I14: 2418393.7 | J14: 4193558.2 | K14: 13049645 | L14: 4511388 | M14: 5866465.9 | N14: 25021589 | O14: 2855374.2 | P14: 9613566.8 | Q14: 13104113 | R14: 3645406.9 | S14: 4860663.3 | T14: 17475256 | U14: 2980399.2 | V14: 5124560.5 | W14: 13392256 | X14: 7549982.1 | Y14: 6990819 | Z14: 31280530 | AA14: 3173399.1 | AB14: 3863831.4 | AC14: 19871075 | AD14: 2809176.6 | AE14: 7664037.1 | AF14: 18669337 | AG14: 3985348.8 | AH14: 7156847.5 | AI14: 18319095 | AJ14: 2182779.9 | AK14: 8783838.8 | AL14: 45364892 | AM14: 2459665.5 | AN14: 2979846.3 | AO14: 7247208 | AP14: 164808.72 | AQ14: 2405896.5 | AR14: 14791818 | AS14: 1620266.6 | AT14: 3748034.5 | AU14: 9684952.2 | AV14: 3125876.1 | AW14: 2655717 | AX14: 12884125 | AY14: 2839786.2 | AZ14: 3613317.9 | BA14: 6791751.2 | BB14: 4147515.3 | BC14: 6823062.3 | BD14: 10837825 | BE14: 5550111.9 | BF14: 4844530.2 | BG14: 10334253 | BH14: 2596722.2 | BI14: 5758677.7 | BJ14: 19038609 | BK14: 6111906.9 | BL14: 5244932.8 | BM14: 15056783 | BN14: 3888036.7 | BO14: 4903536.5 | BP14: 17014172 | BQ14: 3386555.7 | BR14: 7255400.4 | BS14: 19659548 | BT14: 4575956.5 | BU14: 7957090.2 | BV14: 20252006 | BW14: 4493277.4 | BX14: 9271270 | BY14: 21770871 | BZ14: 8237134 | CA14: 12875098 | CB14: 15018510 | CC14: 6243649.9 | CD14: 12477690 | CE14: 14878118 | CF14: 6394099.4 | CG14: 10112082 | CH14: 16321665 | CI14: 4652676.4 | CJ14: 6883303.6 | CK14: 17550994 | CL14: 5094494 | CM14: 7460820.8 | CN14: 21001170 | CO14: 3127999.2 | CP14: 6293990.3 | CQ14: 15999742 | CR14: 6059769.6 | CS14: 7728167.4 | CT14: 34602767 | CU14: 3534895.2 | CV14: 8319033.3 | CW14: 17481764 | CX14: 3887789.2 | CY14: 6567825.1 | CZ14: 18248167 | DA14: 5009594.8 | DB14: 9010715.1 | DC14: 17800299 | DD14: 7951970.2 | DE14: 9351362.4 | DF14: 22943562
B15: Net Revenue | C15: 3888041.1 | D15: 8932763.9 | E15: 37375148 | F15: 5746912 | G15: 25910467 | H15: 40514082 | I15: 8095032.6 | J15: 9418745 | K15: 28135962 | L15: 4568184.8 | M15: 16452131 | N15: 50411512 | O15: 5509071.1 | P15: 11707370 | Q15: 32075641 | R15: 6266446.2 | S15: 16613592 | T15: 38609285 | U15: 8580794.8 | V15: 10863338 | W15: 33918816 | X15: 15021088 | Y15: 17013887 | Z15: 62456939 | AA15: 6875354.3 | AB15: 7464479.4 | AC15: 48473536 | AD15: 9017826.3 | AE15: 17547050 | AF15: 45735110 | AG15: 10132459 | AH15: 17148497 | AI15: 45875991 | AJ15: 6115753.1 | AK15: 22492872 | AL15: 81329017 | AM15: 6136420.1 | AN15: 8272241.2 | AO15: 15191273 | AP15: 1202356.3 | AQ15: 8001855.7 | AR15: 30638800 | AS15: 4888318.2 | AT15: 9398406.4 | AU15: 22567288 | AV15: 8810212.6 | AW15: 7713318 | AX15: 30301874 | AY15: 7961990.8 | AZ15: 10938885 | BA15: 21395779 | BB15: 10775885 | BC15: 14519864 | BD15: 31966015 | BE15: 15278592 | BF15: 14371953 | BG15: 25618272 | BH15: 8427678.8 | BI15: 17538775 | BJ15: 52030820 | BK15: 19599645 | BL15: 18281636 | BM15: 40952649 | BN15: 11854248 | BO15: 15208030 | BP15: 49470507 | BQ15: 11843162 | BR15: 27999181 | BS15: 62275865 | BT15: 16324493 | BU15: 35888447 | BV15: 63695650 | BW15: 19353795 | BX15: 26055498 | BY15: 59357650 | BZ15: 21666919 | CA15: 37935952 | CB15: 45909717 | CC15: 19515255 | CD15: 37115289 | CE15: 44854357 | CF15: 23853271 | CG15: 33136181 | CH15: 52404985 | CI15: 11855163 | CJ15: 22003922 | CK15: 51745923 | CL15: 14535567 | CM15: 17963275 | CN15: 51486496 | CO15: 14700405 | CP15: 26909375 | CQ15: 52147126 | CR15: 18261743 | CS15: 27621124 | CT15: 86911845 | CU15: 10348401 | CV15: 20361155 | CW15: 47572586 | CX15: 8479545.6 | CY15: 18498253 | CZ15: 43302814 | DA15: 13977460 | DB15: 33049974 | DC15: 51695547 | DD15: 24349123 | DE15: 33044697 | DF15: 87220467
B16: Cost | C16: 1878264.3 | D16: 4016685.1 | E16: 18344093 | F16: 2777695.9 | G16: 11819916 | H16: 22433121 | I16: 1252562.4 | J16: 3285636.1 | K16: 14139044 | L16: 2969694.6 | M16: 8475910.2 | N16: 27835192 | O16: 3316048.1 | P16: 8066643.3 | Q16: 16278132 | R16: 3361643 | S16: 7327856.9 | T16: 20028282 | U16: 4650028.8 | V16: 5436703.8 | W16: 15683121 | X16: 8499638.2 | Y16: 8728681.2 | Z16: 37720244 | AA16: 3045986.4 | AB16: 4021982.8 | AC16: 22147520 | AD16: 3906013.2 | AE16: 8496589.4 | AF16: 20025565 | AG16: 4490134.2 | AH16: 7672951.1 | AI16: 20590117 | AJ16: 2971043.2 | AK16: 10145487 | AL16: 0 | AM16: 0 | AN16: 0 | AO16: 0 | AP16: 0 | AQ16: 0 | AR16: 0 | AS16: 0 | AT16: 0 | AU16: 0 | AV16: 0 | AW16: 0 | AX16: 0 | AY16: 0 | AZ16: 0 | BA16: 0 | BB16: 0 | BC16: 0 | BD16: 0 | BE16: 0 | BF16: 0 | BG16: 0 | BH16: 0 | BI16: 0 | BJ16: 0 | BK16: 0 | BL16: 0 | BM16: 0 | BN16: 0 | BO16: 0 | BP16: 0 | BQ16: 0 | BR16: 0 | BS16: 0 | BT16: 0 | BU16: 1 | BV16: 0 | BW16: 1 | BX16: 2 | BY16: 0 | BZ16: 0 | CA16: 0 | CB16: 0 | CC16: 0 | CD16: 0 | CE16: 0 | CF16: 0 | CG16: 0 | CH16: 1 | CI16: 0 | CJ16: 0 | CK16: 0 | CL16: 0 | CM16: 0 | CN16: 0 | CO16: 0 | CP16: 0 | CQ16: 0 | CR16: 0 | CS16: 0 | CT16: 0 | CU16: 0 | CV16: 0 | CW16: 0 | CX16: 0 | CY16: 0 | CZ16: 0 | DA16: 0 | DB16: 0 | DC16: 0 | DD16: 0 | DE16: 1 | DF16: 2
B17: Profit (Excl. Freight & NRV) | C17: 2009776.9 | D17: 4916078.7 | E17: 19031056 | F17: 2969216.1 | G17: 14090551 | H17: 18080961 | I17: 6842470.2 | J17: 6133108.9 | K17: 13996917 | L17: 1598490.2 | M17: 7976220.4 | N17: 22576320 | O17: 2193023 | P17: 3640726.4 | Q17: 15797509 | R17: 2904803.2 | S17: 9285734.8 | T17: 18581003 | U17: 3930766 | V17: 5426634.7 | W17: 18235695 | X17: 6521449.6 | Y17: 8285206.1 | Z17: 24736694 | AA17: 3829367.9 | AB17: 3442496.6 | AC17: 26326017 | AD17: 5111813.2 | AE17: 9050460.6 | AF17: 25709545 | AG17: 5642324.3 | AH17: 9475545.9 | AI17: 25285874 | AJ17: 3144709.8 | AK17: 12347385 | AL17: 81329017 | AM17: 6136420.1 | AN17: 8272241.2 | AO17: 15191273 | AP17: 1202356.3 | AQ17: 8001855.7 | AR17: 30638800 | AS17: 4888318.2 | AT17: 9398406.4 | AU17: 22567288 | AV17: 8810212.6 | AW17: 7713318 | AX17: 30301874 | AY17: 7961990.8 | AZ17: 10938885 | BA17: 21395779 | BB17: 10775885 | BC17: 14519864 | BD17: 31966015 | BE17: 15278592 | BF17: 14371953 | BG17: 25618272 | BH17: 8427678.8 | BI17: 17538775 | BJ17: 52030820 | BK17: 19599645 | BL17: 18281636 | BM17: 40952649 | BN17: 11854248 | BO17: 15208030 | BP17: 49470507 | BQ17: 11843162 | BR17: 27999181 | BS17: 62275865 | BT17: 16324493 | BU17: 35888446 | BV17: 63695650 | BW17: 19353794 | BX17: 26055496 | BY17: 59357650 | BZ17: 21666919 | CA17: 37935952 | CB17: 45909717 | CC17: 19515255 | CD17: 37115289 | CE17: 44854357 | CF17: 23853271 | CG17: 33136181 | CH17: 52404984 | CI17: 11855163 | CJ17: 22003922 | CK17: 51745923 | CL17: 14535567 | CM17: 17963275 | CN17: 51486496 | CO17: 14700405 | CP17: 26909375 | CQ17: 52147126 | CR17: 18261743 | CS17: 27621124 | CT17: 86911845 | CU17: 10348401 | CV17: 20361155 | CW17: 47572586 | CX17: 8479545.6 | CY17: 18498253 | CZ17: 43302814 | DA17: 13977460 | DB17: 33049974 | DC17: 51695547 | DD17: 24349123 | DE17: 33044696 | DF17: 87220465
B19: Check for variances post close | C19: =C4-C13 -> 0 | D19: =D4-D13 -> 0 | E19: =E4-E13 -> 0 | F19: =F4-F13 -> 0 | G19: =G4-G13 -> 0 | H19: =H4-H13 -> 0 | I19: =I4-I13 -> 0 | J19: =J4-J13 -> 0 | ... DF19: =DF4-DF13 -> 0
B20: Check for variances post close | C20: =C5-C14 -> -14958 | D20: =D5-D14 -> 0 | E20: =E5-E14 -> -13448 | F20: =F5-F14 -> 14958 | G20: =G5-G14 -> 0 | H20: =H5-H14 -> -10388 | I20: =I5-I14 -> 0 | J20: =J5-J14 -> 0 | ... DF20: =DF5-DF14 -> 0
B21: Check for variances post close | C21: =C6-C15 -> 14958 | D21: =D6-D15 -> 0 | E21: =E6-E15 -> 13448 | F21: =F6-F15 -> -14958 | G21: =G6-G15 -> 0 | H21: =H6-H15 -> 10388 | I21: =I6-I15 -> 0 | J21: =J6-J15 -> 0 | ... DF21: =DF6-DF15 -> 0
B22: Check for variances post close | C22: =C7-C16 -> -1878264.3 | D22: =D7-D16 -> -4016685.1 | E22: =E7-E16 -> -18344093 | F22: =F7-F16 -> -2777695.9 | G22: =G7-G16 -> -11819916 | H22: =H7-H16 -> -22433121 | I22: =I7-I16 -> -1252562.4 | J22: =J7-J16 -> -3285636.1 | ... BW22: =BW7-BW16 -> 0 | BX22: 0 | BY22: 0 | BZ22: =BZ7-BZ16 -> 0 | CA22: =CA7-CA16 -> 0 | CB22: =CB7-CB16 -> 0 | CC22: =CC7-CC16 -> 0 | CD22: =CD7-CD16 -> 0 | CE22: =CE7-CE16 -> 0 | CF22: =CF7-CF16 -> 0 | CG22: =CG7-CG16 -> 0 | ... DF22: =DF7-DF16 -> 0
B23: Check for variances post close | C23: =C8-C17 -> 1893222.3 | D23: =D8-D17 -> 4016685.2 | E23: =E8-E17 -> 18357541 | F23: =F8-F17 -> 2762737.9 | G23: =G8-G17 -> 11819916 | H23: =H8-H17 -> 22443509 | I23: =I8-I17 -> 1252562.4 | J23: =J8-J17 -> 3285636.1 | ... BW23: =BW8-BW17 -> 0 | BX23: 0 | BY23: 0 | BZ23: =BZ8-BZ17 -> 0 | CA23: =CA8-CA17 -> 0 | CB23: =CB8-CB17 -> 0 | CC23: =CC8-CC17 -> 0 | CD23: =CD8-CD17 -> 0 | CE23: =CE8-CE17 -> 0 | CF23: =CF8-CF17 -> 0 | CG23: =CG8-CG17 -> 0 | ... DF23: =DF8-DF17 -> 0
B25: TRANSPOSE AND ADD NA
C26: BPC Plug Beginning Month Date | D26: BPC Plug Gross Revenue (less Freight) | E26: BPC Plug Discount | F26: BPC Plug Net Revenue | G26: BPC Plug Cost | H26: BPC Plug Profit | I26: PC Region
C27: 42736 | D27: 5676622.3 | E27: 1788581.2 | F27: 3888041.1 | G27: 1878264.3 | H27: 2009776.9 | I27: NA
C28: 42767 | D28: 11789195 | E28: 2856430.6 | F28: 8932763.9 | G28: 4016685.1 | H28: 4916078.7 | I28: NA
C29: 42795 | D29: 51980266 | E29: 14605118 | F29: 37375148 | G29: 18344093 | H29: 19031056 | I29: NA
C30: 42826 | D30: 7298743.2 | E30: 1551831.2 | F30: 5746912 | G30: 2777695.9 | H30: 2969216.1 | I30: NA
C31: 42856 | D31: 37143606 | E31: 11233139 | F31: 25910467 | G31: 11819916 | H31: 14090551 | I31: NA
C32: 42887 | D32: 56309810 | E32: 15795728 | F32: 40514082 | G32: 22433121 | H32: 18080961 | I32: NA
C33: 42917 | D33: 10513426 | E33: 2418393.7 | F33: 8095032.6 | G33: 1252562.4 | H33: 6842470.2 | I33: NA
C34: 42948 | D34: 13612303 | E34: 4193558.2 | F34: 9418745 | G34: 3285636.1 | H34: 6133108.9 | I34: NA
C35: 42979 | D35: 41185607 | E35: 13049645 | F35: 28135962 | G35: 14139044 | H35: 13996917 | I35: NA
C36: 43009 | D36: 9079572.8 | E36: 4511388 | F36: 4568184.8 | G36: 2969694.6 | H36: 1598490.2 | I36: NA
C37: 43040 | D37: 22318596 | E37: 5866465.9 | F37: 16452131 | G37: 8475910.2 | H37: 7976220.4 | I37: NA
C38: 43070 | D38: 75433100 | E38: 25021589 | F38: 50411512 | G38: 27835192 | H38: 22576320 | I38: NA
... C42: 43191 | D42: 9911853.1 | E42: 3645406.9 | F42: 6266446.2 | G42: 3361643 | H42: 2904803.2 | I42: NA
B43: EDIT TOP 200 ROWS into BPC_Plug_Financials Table in SQL | C43: 43221 | D43: 21474255 | E43: 4860663.3 | F43: 16613592 | G43: 7327856.9 | H43: 9285734.8 | I43: NA
C44: 43252 | D44: 56084541 | E44: 17475256 | F44: 38609285 | G44: 20028282 | H44: 18581003 | I44: NA
C45: 43282 | D45: 11561194 | E45: 2980399.2 | F45: 8580794.8 | G45: 4650028.8 | H45: 3930766 | I45: NA
C46: 43313 | D46: 15987899 | E46: 5124560.5 | F46: 10863338 | G46: 5436703.8 | H46: 5426634.7 | I46: NA
C47: 43344 | D47: 47311072 | E47: 13392256 | F47: 33918816 | G47: 15683121 | H47: 18235695 | I47: NA
C48: 43374 | D48: 22571070 | E48: 7549982.1 | F48: 15021088 | G48: 8499638.2 | H48: 6521449.6 | I48: NA
C49: 43405 | D49: 24004706 | E49: 6990819 | F49: 17013887 | G49: 8728681.2 | H49: 8285206.1 | I49: NA
...

Sheet Ad Hoc BPC Data Linked
A1: =_xll.EPMOlapMemberO("[PROFITCENTER].[PARENTH1].[01NAMGMINT01]","","01NAMGMINT01 - North America Gaming","","000") -> 01NAMGMINT01 - North America Gaming
A2: =_xll.EPMOlapMemberO("[PROBABILITY].[PARENTH2].[PLAN]","","Plan","","000") -> Plan
A3: =_xll.EPMOlapMemberO("[FUNCTIONALAREA].[PARENTH2].[PROD]","","PROD - Product","","000") -> PROD - Product
A4: =_xll.EPMOlapMemberO("[VERSION].[PARENTH1].[ACTUAL]","","Actual","","000") -> Actual
A5: =_xll.EPMOlapMemberO("[INPUTCURRENCY].[PARENTH1].[30]","","USD","","000") -> USD
A6: =_xll.EPMOlapMemberO("[GAME].[PARENTH1].[ALL_GAME]","","All Games","","000") -> All Games
A7: =_xll.EPMOlapMemberO("[PRODUCT].[PARENTH1].[ALL_PROD]","","All Products","","000") -> All Products
A8: =_xll.EPMOlapMemberO("[MEASURES].[].[PERIODIC]","","Periodic","","000") -> Periodic
B10: =_xll.EPMOlapMemberO("[TIME].[PARENTH1].[2019.JAN]","","2019.JAN - Jan-19","","000") -> 2019.JAN - Jan-19 | C10: =_xll.EPMOlapMemberO("[TIME].[PARENTH1].[2019.FEB]","","2019.FEB - Feb-19","","000") -> 2019.FEB - Feb-19 | D10: =_xll.EPMOlapMemberO("[TIME].[PARENTH1].[2019.MAR]","","2019.MAR - Mar-19","","000") -> 2019.MAR - Mar-19 | E10: =_xll.EPMOlapMemberO("[TIME].[PARENTH1].[2019.APR]","","2019.APR - Apr-19","","000") -> 2019.APR - Apr-19 | F10: =_xll.EPMOlapMemberO("[TIME].[PARENTH1].[2019.MAY]","","2019.MAY - May-19","","000") -> 2019.MAY - May-19 | G10: =_xll.EPMOlapMemberO("[TIME].[PARENTH1].[2019.JUN]","","2019.JUN - Jun-19","","000") -> 2019.JUN - Jun-19 | H10: =_xll.EPMOlapMemberO("[TIME].[PARENTH1].[2019.JUL]","","2019.JUL - Jul-19","","000") -> 2019.JUL - Jul-19 | I10: =_xll.EPMOlapMemberO("[TIME].[PARENTH1].[2019.AUG]","","2019.AUG - Aug-19","","000") -> 2019.AUG - Aug-19 | J10: =_xll.EPMOlapMemberO("[TIME].[PARENTH1].[2019.SEP]","","2019.SEP - Sep-19","","000") -> 2019.SEP - Sep-19 | K10: =_xll.EPMOlapMemberO("[TIME].[PARENTH1].[2019.OCT]","","2019.OCT - Oct-19","","000") -> 2019.OCT - Oct-19 | L10: =_xll.EPMOlapMemberO("[TIME].[PARENTH1].[2019.NOV]","","2019.NOV - Nov-19","","000") -> 2019.NOV - Nov-19 | M10: =_xll.EPMOlapMemberO("[TIME].[PARENTH1].[2019.DEC]","","2019.DEC - Dec-19","","000") -> 2019.DEC - Dec-19 | N10: =_xll.EPMOlapMemberO("[TIME].[PARENTH1].[2020.JAN]","","2020.JAN - Jan-20","","000") -> 2020.JAN - Jan-20 | O10: =_xll.EPMOlapMemberO("[TIME].[PARENTH1].[2020.FEB]","","2020.FEB - Feb-20","","000") -> 2020.FEB - Feb-20 | P10: =_xll.EPMOlapMemberO("[TIME].[PARENTH1].[2020.MAR]","","2020.MAR - Mar-20","","000") -> 2020.MAR - Mar-20 | Q10: =_xll.EPMOlapMemberO("[TIME].[PARENTH1].[2020.APR]","","2020.APR - Apr-20","","000") -> 2020.APR - Apr-20 | R10: =_xll.EPMOlapMemberO("[TIME].[PARENTH1].[2020.MAY]","","2020.MAY - May-20","","000") -> 2020.MAY - May-20 | S10: =_xll.EPMOlapMemberO("[TIME].[PARENTH1].[2020.JUN]","","2020.JUN - Jun-20","","000") -> 2020.JUN - Jun-20 | T10: =_xll.EPMOlapMemberO("[TIME].[PARENTH1].[2020.JUL]","","2020.JUL - Jul-20","","000") -> 2020.JUL - Jul-20 | U10: =_xll.EPMOlapMemberO("[TIME].[PARENTH1].[2020.AUG]","","2020.AUG - Aug-20","","000") -> 2020.AUG - Aug-20 | V10: =_xll.EPMOlapMemberO("[TIME].[PARENTH1].[2020.SEP]","","2020.SEP - Sep-20","","000") -> 2020.SEP - Sep-20 | W10: =_xll.EPMOlapMemberO("[TIME].[PARENTH1].[2020.OCT]","","2020.OCT - Oct-20","","000") -> 2020.OCT - Oct-20 | X10: =_xll.EPMOlapMemberO("[TIME].[PARENTH1].[2020.NOV]","","2020.NOV - Nov-20","","000") -> 2020.NOV - Nov-20 | Y10: =_xll.EPMOlapMemberO("[TIME].[PARENTH1].[2020.DEC]","","2020.DEC - Dec-20","","000") -> 2020.DEC - Dec-20 | Z10: =_xll.EPMOlapMemberO("[TIME].[PARENTH1].[2021.JAN]","","2021.JAN - Jan-21","","000") -> 2021.JAN - Jan-21 | AA10: =_xll.EPMOlapMemberO("[TIME].[PARENTH1].[2021.FEB]","","2021.FEB - Feb-21","","000") -> 2021.FEB - Feb-21 | AB10: =_xll.EPMOlapMemberO("[TIME].[PARENTH1].[2021.MAR]","","2021.MAR - Mar-21","","000") -> 2021.MAR - Mar-21 | AC10: =_xll.EPMOlapMemberO("[TIME].[PARENTH1].[2021.APR]","","2021.APR - Apr-21","","000") -> 2021.APR - Apr-21 | AD10: =_xll.EPMOlapMemberO("[TIME].[PARENTH1].[2021.MAY]","","2021.MAY - May-21","","000") -> 2021.MAY - May-21 | AE10: =_xll.EPMOlapMemberO("[TIME].[PARENTH1].[2021.JUN]","","2021.JUN - Jun-21","","000") -> 2021.JUN - Jun-21 | AF10: =_xll.EPMOlapMemberO("[TIME].[PARENTH1].[2021.JUL]","","2021.JUL - Jul-21","","000") -> 2021.JUL - Jul-21 | AG10: =_xll.EPMOlapMemberO("[TIME].[PARENTH1].[2021.AUG]","","2021.AUG - Aug-21","","000") -> 2021.AUG - Aug-21 | AH10: =_xll.EPMOlapMemberO("[TIME].[PARENTH1].[2021.SEP]","","2021.SEP - Sep-21","","000") -> 2021.SEP - Sep-21 | AI10: =_xll.EPMOlapMemberO("[TIME].[PARENTH1].[2021.OCT]","","2021.OCT - Oct-21","","000") -> 2021.OCT - Oct-21 | AJ10: =_xll.EPMOlapMemberO("[TIME].[PARENTH1].[2021.NOV]","","2021.NOV - Nov-21","","000") -> 2021.NOV - Nov-21 | AK10: =_xll.EPMOlapMemberO("[TIME].[PARENTH1].[2021.DEC]","","2021.DEC - Dec-21","","000") -> 2021.DEC - Dec-21 | AL10: =_xll.EPMOlapMemberO("[TIME].[PARENTH1].[2022.JAN]","","2022.JAN - Jan-22","","000") -> 2022.JAN - Jan-22 | AM10: =_xll.EPMOlapMemberO("[TIME].[PARENTH1].[2022.FEB]","","2022.FEB - Feb-22","","000") -> 2022.FEB - Feb-22 | AN10: =_xll.EPMOlapMemberO("[TIME].[PARENTH1].[2022.MAR]","","2022.MAR - Mar-22","","000") -> 2022.MAR - Mar-22 | AO10: =_xll.EPMOlapMemberO("[TIME].[PARENTH1].[2022.APR]","","2022.APR - Apr-22","","000") -> 2022.APR - Apr-22 | AP10: =_xll.EPMOlapMemberO("[TIME].[PARENTH1].[2022.MAY]","","2022.MAY - May-22","","000") -> 2022.MAY - May-22 | AQ10: =_xll.EPMOlapMemberO("[TIME].[PARENTH1].[2022.JUN]","","2022.JUN - Jun-22","","000") -> 2022.JUN - Jun-22 | AR10: =_xll.EPMOlapMemberO("[TIME].[PARENTH1].[2022.JUL]","","2022.JUL - Jul-22","","000") -> 2022.JUL - Jul-22 | AS10: =_xll.EPMOlapMemberO("[TIME].[PARENTH1].[2022.AUG]","","2022.AUG - Aug-22","","000") -> 2022.AUG - Aug-22 | AT10: =_xll.EPMOlapMemberO("[TIME].[PARENTH1].[2022.SEP]","","2022.SEP - Sep-22","","000") -> 2022.SEP - Sep-22 | AU10: =_xll.EPMOlapMemberO("[TIME].[PARENTH1].[2022.OCT]","","2022.OCT - Oct-22","","000") -> 2022.OCT - Oct-22 | AV10: =_xll.EPMOlapMemberO("[TIME].[PARENTH1].[2022.NOV]","","2022.NOV - Nov-22","","000") -> 2022.NOV - Nov-22 | AW10: =_xll.EPMOlapMemberO("[TIME].[PARENTH1].[2022.DEC]","","2022.DEC - Dec-22","","000") -> 2022.DEC - Dec-22 | AX10: =_xll.EPMOlapMemberO("[TIME].[PARENTH1].[2023.JAN]","","2023.JAN - Jan-23","","000") -> 2023.JAN - Jan-23 | AY10: =_xll.EPMOlapMemberO("[TIME].[PARENTH1].[2023.FEB]","","2023.FEB - Feb-23","","000") -> 2023.FEB - Feb-23 | AZ10: =_xll.EPMOlapMemberO("[TIME].[PARENTH1].[2023.MAR]","","2023.MAR - Mar-23","","000") -> 2023.MAR - Mar-23 | BA10: =_xll.EPMOlapMemberO("[TIME].[PARENTH1].[2023.APR]","","2023.APR - Apr-23","","000") -> 2023.APR - Apr-23 | BB10: =_xll.EPMOlapMemberO("[TIME].[PARENTH1].[2023.MAY]","","2023.MAY - May-23","","000") -> 2023.MAY - May-23 | BC10: =_xll.EPMOlapMemberO("[TIME].[PARENTH1].[2023.JUN]","","2023.JUN - Jun-23","","000") -> 2023.JUN - Jun-23 | BD10: =_xll.EPMOlapMemberO("[TIME].[PARENTH1].[2023.JUL]","","2023.JUL - Jul-23","","000") -> 2023.JUL - Jul-23 | BE10: =_xll.EPMOlapMemberO("[TIME].[PARENTH1].[2023.AUG]","","2023.AUG - Aug-23","","000") -> 2023.AUG - Aug-23 | BF10: =_xll.EPMOlapMemberO("[TIME].[PARENTH1].[2023.SEP]","","2023.SEP - Sep-23","","000") -> 2023.SEP - Sep-23 | BG10: =_xll.EPMOlapMemberO("[TIME].[PARENTH1].[2023.OCT]","","2023.OCT - Oct-23","","000") -> 2023.OCT - Oct-23 | BH10: =_xll.EPMOlapMemberO("[TIME].[PARENTH1].[2023.NOV]","","2023.NOV - Nov-23","","000") -> 2023.NOV - Nov-23 | BI10: =_xll.EPMOlapMemberO("[TIME].[PARENTH1].[2023.DEC]","","2023.DEC - Dec-23","","000") -> 2023.DEC - Dec-23 | BJ10: =_xll.EPMOlapMemberO("[TIME].[PARENTH1].[2024.JAN]","","2024.JAN - Jan-24","","000") -> 2024.JAN - Jan-24 | BK10: =_xll.EPMOlapMemberO("[TIME].[PARENTH1].[2024.FEB]","","2024.FEB - Feb-24","","000") -> 2024.FEB - Feb-24 | BL10: =_xll.EPMOlapMemberO("[TIME].[PARENTH1].[2024.MAR]","","2024.MAR - Mar-24","","000") -> 2024.MAR - Mar-24 | BM10: =_xll.EPMOlapMemberO("[TIME].[PARENTH1].[2024.APR]","","2024.APR - Apr-24","","000") -> 2024.APR - Apr-24 | BN10: =_xll.EPMOlapMemberO("[TIME].[PARENTH1].[2024.MAY]","","2024.MAY - May-24","","000") -> 2024.MAY - May-24 | BO10: =_xll.EPMOlapMemberO("[TIME].[PARENTH1].[2024.JUN]","","2024.JUN - Jun-24","","000") -> 2024.JUN - Jun-24 | BP10: =_xll.EPMOlapMemberO("[TIME].[PARENTH1].[2024.JUL]","","2024.JUL - Jul-24","","000") -> 2024.JUL - Jul-24 | BQ10: =_xll.EPMOlapMemberO("[TIME].[PARENTH1].[2024.AUG]","","2024.AUG - Aug-24","","000") -> 2024.AUG - Aug-24 | BR10: =_xll.EPMOlapMemberO("[TIME].[PARENTH1].[2024.SEP]","","2024.SEP - Sep-24","","000") -> 2024.SEP - Sep-24 | BS10: =_xll.EPMOlapMemberO("[TIME].[PARENTH1].[2024.OCT]","","2024.OCT - Oct-24","","000") -> 2024.OCT - Oct-24 | BT10: =_xll.EPMOlapMemberO("[TIME].[PARENTH1].[2024.NOV]","","2024.NOV - Nov-24","","000") -> 2024.NOV - Nov-24 | BU10: =_xll.EPMOlapMemberO("[TIME].[PARENTH1].[2024.DEC]","","2024.DEC - Dec-24","","000") -> 2024.DEC - Dec-24 | BV10: =_xll.EPMOlapMemberO("[TIME].[PARENTH1].[2025.JAN]","","2025.JAN - Jan-25","","000") -> 2025.JAN - Jan-25 | BW10: =_xll.EPMOlapMemberO("[TIME].[PARENTH1].[2025.FEB]","","2025.FEB - Feb-25","","000") -> 2025.FEB - Feb-25 | BX10: =_xll.EPMOlapMemberO("[TIME].[PARENTH1].[2025.MAR]","","2025.MAR - Mar-25","","000") -> 2025.MAR - Mar-25 | BY10: =_xll.EPMOlapMemberO("[TIME].[PARENTH1].[2025.APR]","","2025.APR - Apr-25","","000") -> 2025.APR - Apr-25 | BZ10: =_xll.EPMOlapMemberO("[TIME].[PARENTH1].[2025.MAY]","","2025.MAY - May-25","","000") -> 2025.MAY - May-25 | CA10: =_xll.EPMOlapMemberO("[TIME].[PARENTH1].[2025.JUN]","","2025.JUN - Jun-25","","000") -> 2025.JUN - Jun-25 | CB10: =_xll.EPMOlapMemberO("[TIME].[PARENTH1].[2025.JUL]","","2025.JUL - Jul-25","","000") -> 2025.JUL - Jul-25 | CC10: =_xll.EPMOlapMemberO("[TIME].[PARENTH1].[2025.AUG]","","2025.AUG - Aug-25","","000") -> 2025.AUG - Aug-25 | CD10: =_xll.EPMOlapMemberO("[TIME].[PARENTH1].[2025.SEP]","","2025.SEP - Sep-25","","000") -> 2025.SEP - Sep-25 | CE10: =_xll.EPMOlapMemberO("[TIME].[PARENTH1].[2025.OCT]","","2025.OCT - Oct-25","","000") -> 2025.OCT - Oct-25 | CF10: =_xll.EPMOlapMemberO("[TIME].[PARENTH1].[2025.NOV]","","2025.NOV - Nov-25","","000") -> 2025.NOV - Nov-25 | CG10: =_xll.EPMOlapMemberO("[TIME].[PARENTH1].[2025.DEC]","","2025.DEC - Dec-25","","000") -> 2025.DEC - Dec-25
A11: =_xll.EPMOlapMemberO("[ACCOUNT].[PARENTH1].[303000]","","EGM Terminals","","000") -> EGM Terminals | B11: 9146017 | C11: 10629328 | D11: 65660450 | E11: 11134963 | F11: 23439954 | G11: 60881541 | H11: 13433601 | I11: 22219237 | J11: 61102869 | K11: 21865961 | L11: 30137074 | M11: 1.0735672e+08 | N11: 7990335.6 | O11: 9214481.5 | P11: 20742315 | Q11: 1352417 | R11: 9705412 | S11: 44025660 | T11: 5451741 | U11: 14367261 | V11: 29278360 | W11: 9794221 | X11: 8794407 | Y11: 34792345 | Z11: 9351119.4 | AA11: 13235762 | AB11: 25479169 | AC11: 13806882 | AD11: 20282817 | AE11: 35291542 | AF11: 18435635 | AG11: 15928816 | AH11: 29545347 | AI11: 16707524 | AJ11: 20065218 | AK11: 59753106 | AL11: 22387452 | AM11: 20594986 | AN11: 53308555 | AO11: 13868162 | AP11: 18043709 | AQ11: 63466246 | AR11: 15243270 | AS11: 33985683 | AT11: 80191716 | AU11: 20247126 | AV11: 42149159 | AW11: 79600367 | AX11: 22420840 | AY11: 34946730 | AZ11: 78412513 | BA11: 29255745 | BB11: 49660755 | BC11: 58573850 | BD11: 24103914 | BE11: 47053269 | BF11: 56545510 | BG11: 29339210 | BH11: 40765088 | BI11: 66820093 | BJ11: 15729106 | BK11: 28201311 | BL11: 68213473 | BM11: 17667865 | BN11: 24501518 | BO11: 67579694 | BP11: 17425899 | BQ11: 32032338 | BR11: 64262763 | BS11: 22984096 | BT11: 34936885 | BU11: 1.1170008e+08 | BV11: 13066264 | BW11: 26649064 | BX11: 60519024 | BY11: 11749768 | BZ11: 23660633 | CA11: 52830349 | CB11: 17720235 | CC11: 40501131 | CD11: 63651998 | CE11: 30491974 | CF11: 34824178 | CG11: 1.0780077e+08
A12: =_xll.EPMOlapMemberO("[ACCOUNT].[PARENTH1].[303050]","","EGM Terminals Collaboration","","000") -> EGM Terminals Collaboration
A13: =_xll.EPMOlapMemberO("[ACCOUNT].[PARENTH1].[303107]","","Terminal Kits","","000") -> Terminal Kits
A14: =_xll.EPMOlapMemberO("[ACCOUNT].[PARENTH1].[303201]","","Vlt Terminal","","000") -> Vlt Terminal
A15: =_xll.EPMOlapMemberO("[ACCOUNT].[PARENTH1].[303209]","","AWP Machines","","000") -> AWP Machines
A16: =_xll.EPMOlapMemberO("[ACCOUNT].[PARENTH1].[303210]","","Frght","","000") -> Frght | B16: 90141.02 | C16: 102204.95 | D16: 343222.46 | E16: 142806.15 | F16: 242843.09 | G16: 336335.21 | H16: 119742.7 | I16: 147434.92 | J16: 416875.35 | K16: 111991.62 | L16: 166075.02 | M16: 593097.67 | N16: 96683 | O16: 86916.43 | P16: 105928.65 | Q16: 1515.97 | R16: 79979.55 | S16: 241758.93 | T16: 48244.85 | U16: 88962.13 | V16: 194458.63 | W16: 143722.3 | X16: 67692 | Y16: 261654.44 | Z16: 57453.07 | AA16: 81634.69 | AB16: 224894.82 | AC16: 83792.51 | AD16: 147517.06 | AE16: 386416.67 | AF16: 248944.84 | AG16: 140527.65 | AH16: 326852.46 | AI16: 94193.88 | AJ16: 540553.95 | AK16: -20510.9 | AL16: 213640.74 | AM16: 144439.52 | AN16: 354238.43 | AO16: 152154.04 | AP16: 127710.75 | AQ16: 537601.58 | AR16: 122153.12 | AS16: 219817.7 | AT16: 557755.88 | AU16: 120696.05 | AV16: 277588.49 | AW16: 508128.36 | AX16: 141081.49 | AY16: 237827.63 | AZ16: 620750.5 | BA16: 218489.35 | BB16: 339003.61 | BC16: 510704.5 | BD16: 190544.05 | BE16: 236114.33 | BF16: 431951.1 | BG16: 205916.62 | BH16: 303125.52 | BI16: 548794.17 | BJ16: 134792.75 | BK16: 244257.24 | BL16: 402810.71 | BM16: 155122.33 | BN16: 292194.46 | BO16: 406448.93 | BP16: 108826.66 | BQ16: 207600.76 | BR16: 446273.95 | BS16: 114215.45 | BT16: 209554.5 | BU16: 822812.07 | BV16: 118292.89 | BW16: 153071.73 | BX16: 407001.54 | BY16: 162214.16 | BZ16: 226775.27 | CA16: 455251.52 | CB16: 199702.91 | CC16: 213225.92 | CD16: 470095.82 | CE16: 277903.45 | CF16: 184116.81 | CG16: 683364.84
A17: =_xll.EPMOlapMemberO("[ACCOUNT].[PARENTH1].[303365]","","New Non-Premium STL Revenue","","000") -> New Non-Premium STL Revenue | AH17: 291918 | AJ17: 260377.5 | AK17: 389135.25 | AM17: 418693 | AN17: 387278.75 | AO17: 816351.16 | AP17: 0 | AS17: 575682.5 | AV17: 270876.25 | AW17: 2327568.6 | AX17: 788510 | AZ17: 1403043.6 | BA17: 368139.42 | BB17: 595259 | BC17: 335077.5 | BE17: 554424.25 | BF17: 182317.5 | BG17: 320791.25 | BH17: 473642 | BI17: 574762.65 | BJ17: -260150.5 | BK17: 155777 | BM17: 1015405.6 | BN17: 350092 | BO17: 2757172.2 | BQ17: 1123974 | BR17: 103233.89 | BS17: 335793 | BT17: 657246.25 | BU17: 11200 | BV17: 10500 | BW17: 245171.32 | BX17: 138299 | BZ17: 150362.5 | CA17: 2030796 | CE17: 28572 | CF17: 289897.33 | CG17: 2800
A18: =_xll.EPMOlapMemberO("[ACCOUNT].[PARENTH1].[303630]","","MPS Mach Revenue","","000") -> MPS Mach Revenue
A19: =_xll.EPMOlapMemberO("[ACCOUNT].[PARENTH1].[303632]","","Sales Disc Mach","","000") -> Sales Disc Mach | B19: -2574765 | C19: -3069027.9 | D19: -18597063 | E19: -2901856.5 | F19: -6646994.3 | G19: -17184096 | H19: -3626089.5 | I19: -6375982.3 | J19: -16513318 | K19: -7462117.4 | L19: -8402360.8 | M19: -35577473 | N19: -2198028 | O19: -2570456.9 | P19: -6567010.7 | Q19: -182623.89 | R19: -2030897.6 | S19: -14155641 | T19: -1266101.6 | U19: -3782096.4 | V19: -8296033.8 | W19: -2501835.9 | X19: -2365957.2 | Y19: -10416637 | Z19: -2437930 | AA19: -3276983.7 | AB19: -5705092.4 | AC19: -3785446.3 | AD19: -6382025 | AE19: -8496353.2 | AF19: -4711442.8 | AG19: -3594952.1 | AH19: -8330173.3 | AI19: -3530302.3 | AJ19: -4960487.2 | AK19: -16154535 | AL19: -4943795.9 | AM19: -4738010.9 | AN19: -14053069 | AO19: -3016189.5 | AP19: -4324974.6 | AQ19: -15330349 | AR19: -3220703.1 | AS19: -6943698.7 | AT19: -18310352 | AU19: -3797905.4 | AV19: -6259325.7 | AW19: -19043978 | AX19: -3935532.7 | AY19: -8797613.4 | AZ19: -20040297 | BA19: -7788992.3 | BB19: -11620171 | BC19: -14153184 | BD19: -5214537.8 | BE19: -11380374 | BF19: -11425148 | BG19: -5347955.5 | BH19: -9236736.2 | BI19: -15121656 | BJ19: -3184255 | BK19: -6621193.6 | BL19: -16515801 | BM19: -4484153.1 | BN19: -6484555.6 | BO19: -17871739 | BP19: -2683702.6 | BQ19: -6134774.3 | BR19: -14456696 | BS19: -4308808.1 | BT19: -7030668.9 | BU19: -30731996 | BV19: -2875643.4 | BW19: -7794541.8 | BX19: -14698004 | BY19: -3287454.2 | BZ19: -5708823.2 | CA19: -15892510 | CB19: -3116145.2 | CC19: -8480465.7 | CD19: -15270938 | CE19: -8155852 | CF19: -6762186.8 | CG19: -21230513
A20: =_xll.EPMOlapMemberO("[ACCOUNT].[PARENTH1].[303633]","","Mach Discount Recovery","","000") -> Mach Discount Recovery | W20: 78043.3 | X20: -17970 | Y20: 56540.44 | Z20: -55668.42 | AC20: 663.05 | AI20: 900.76 | AJ20: -5.87 | AW20: 6607.53 | BG20: 1329.13 | BH20: 500 | BW20: 29515.61 | BY20: 0 | BZ20: 103935.54 | CC20: -27465.83
A21: =_xll.EPMOlapMemberO("[ACCOUNT].[PARENTH1].[303634]","","Disc Dfrd Int Mach","","000") -> Disc Dfrd Int Mach | D21: 2641.72 | F21: 5428.32 | K21: 3940 | M21: -1226562.2 | N21: 258303.71 | X21: 158261.46 | AY21: -3338.37 | AZ21: -166468.12 | BA21: -12385.32 | BB21: -189567.55 | BC21: -24339.03 | BD21: -1880.72 | BE21: -121065.23 | BF21: -252359.05 | BG21: -7127.25 | BH21: -100909.94 | BI21: -102029.2 | BJ21: -7144.85 | BK21: 32322.76 | BL21: -172855.07 | BM21: -1997.39 | BN21: -26681.13 | BO21: -329587.15 | BQ21: -275.45 | BR21: -39826.78 | BS21: -122026.8 | BU21: -167503.85 | BV21: -7423.56 | BW21: -5772.83 | BX21: 29443.29 | BY21: -3711.16 | BZ21: -5164.92 | CA21: -19428.21 | CB21: -9553.21 | CC21: -24733.42 | CD21: -22691.69 | CE21: -20794.15 | CF21: -22069.54 | CG21: -66565.16
A22: =_xll.EPMOlapMemberO("[ACCOUNT].[PARENTH1].[303635]","","Theme Discounts","","000") -> Theme Discounts
A23: =_xll.EPMOlapMemberO("[ACCOUNT].[PARENTH1].[303637]","","Cash Discount","","000") -> Cash Discount | B23: 19998.06 | C23: -33861.51 | D23: -96683.4 | E23: 67726.25 | F23: -97015.04 | G23: -11168.9 | H23: -37123.97 | I23: -49666.83 | J23: 20006.15 | K23: 3608.9 | L23: -47656.72 | M23: -57626.22 | N23: -21484.47 | O23: -7607.29 | P23: -9725.5 | Q23: 17067.32 | R23: -618.91 | S23: -3018.65 | T23: -4085.8 | U23: -22698.63 | V23: -46001.13 | W23: 63610.74 | X23: -6198.56 | Y23: -6907.91 | Z23: -14.23 | AA23: 568.36 | AB23: -25362.15 | AC23: -615.26 | AD23: -30273.13 | AE23: -10924.22 | AF23: 10599.64 | AG23: -107653.34 | AK23: -27061.07 | AL23: 0.04 | AP23: -3851.74 | AQ23: 3851.74 | AV23: -9441.98 | AW23: -1499.64 | AZ23: -9240.85 | BA23: -375.85 | BB23: 375.85 | CC23: -11.8 | CG23: -0.43
A24: =_xll.EPMOlapMemberO("[ACCOUNT].[PARENTH1].[303641]","","Machine Concession","","000") -> Machine Concession | U24: -97.17 | AW24: -400 | AY24: -2129.69 | BH24: -17993.2
A25: =_xll.EPMOlapMemberO("[ACCOUNT].[PARENTH1].[303644]","","Parts Coupon Discount New","","000") -> Parts Coupon Discount New | B25: -435208.51 | C25: -719405 | D25: -605255.84 | E25: 242850 | F25: -543082.2 | G25: -472792 | H25: -123284.11 | I25: -277000 | J25: -818715 | K25: -305688.15 | L25: -188874.28 | M25: -1596800.7 | N25: -353130 | O25: -181071.6 | P25: -221824.05 | Q25: 747.85 | R25: -9000 | S25: -41500 | T25: -27000 | U25: -194020 | V25: -514877.24 | W25: -235921.16 | X25: -29360 | Y25: -79720 | Z25: -16681 | AA25: 1385 | AB25: -45813.6 | AC25: -233929 | AD25: -151859.42 | AE25: -39345 | AF25: -126496 | AG25: -45318 | AH25: -88958 | AI25: -75000 | AJ25: -43338.15 | AK25: -49012.09 | AL25: -448135 | AM25: -48970 | AN25: -495650 | AO25: -479390 | AP25: -309225 | AQ25: -874989.46 | AR25: -101556.84 | AS25: -39684.53 | AT25: -1005249.5 | AU25: -598214.2 | AV25: -1253725.9 | AW25: -1595.42 | AX25: -260437.1 | AY25: -396428.59 | AZ25: -644846.75 | BA25: -195097.64 | BB25: -688810.58 | BC25: -168135 | BD25: -547595.99 | BE25: -247707.05 | BF25: -2437271.6 | BG25: -792292.11 | BH25: -290116.48 | BI25: -787440.8 | BJ25: -1104266.9 | BK25: -164421.25 | BL25: -524327.87 | BM25: -88714.69 | BN25: -599460.59 | BO25: -1556086.1 | BP25: -330045.52 | BQ25: -46349.27 | BR25: -973284.56 | BS25: -850840.36 | BT25: -317095.46 | BU25: -1135124.1 | BV25: -399906.12 | BW25: 12971.3 | BX25: -1253984.1 | BY25: -392482.16 | BZ25: -533837.44 | CA25: -612456.03 | CB25: -440974.65 | CC25: -66346.86 | CD25: -459163.32 | CE25: -95074.45 | CF25: -136420.21 | CG25: -1018537.3
A26: =_xll.EPMOlapMemberO("[ACCOUNT].[PARENTH1].[303647]","","LTG Machine Rev","","000") -> LTG Machine Rev | B26: -1166 | D26: 657363.47 | E26: 69000 | F26: 476968 | G26: 1196000 | I26: 1187860 | J26: -250 | K26: 25929.05 | L26: 187237.25 | M26: 313584.5 | N26: 2462.15 | Q26: 14748 | R26: -14995.8 | S26: 422482.54 | T26: 334449.78 | U26: -1259.25 | V26: 13224.29 | W26: 602044.68 | X26: 290217 | Y26: 761814.82 | AB26: 4672.75 | AC26: 337979.66 | AE26: 460000 | AH26: 2162 | AI26: 287958 | AK26: 651976 | AL26: 1407618.3 | AM26: 276000 | AN26: 28 | AO26: 126966.5 | AP26: -126966.51 | AR26: -5810.21 | AT26: 36000 | AU26: 134991 | AV26: 284938 | BA26: 1507.65 | BD26: 12580.84 | BF26: 814.2 | BH26: -48148.6 | BI26: 289320 | BL26: 101760.8 | BO26: 160906 | BY26: 26827.3 | CE26: 1725178.2 | CG26: 432379.01
A27: =_xll.EPMOlapMemberO("[ACCOUNT].[PARENTH1].[303650]","","LTG Machine Discounts","","000") -> LTG Machine Discounts | D27: -131472.69 | E27: -14250 | F27: -120468 | G27: -386130.73 | I27: -340599.98 | L27: -38778 | M27: -61644.5 | N27: -771.65 | S27: -141248.5 | T27: -66458.63 | V27: -3067.05 | W27: -80270.04 | X27: -93198.76 | Y27: -158534.25 | AB27: -5120.1 | AC27: -76815.38 | AD27: -8000 | AE27: -93800 | AG27: -4000 | AH27: 1838 | AI27: -129294 | AK27: -163392.8 | AL27: -317491.59 | AM27: -63480 | AN27: 5992.6 | AU27: -33747.75 | AV27: -100616.29 | BI27: -106759.08 | BQ27: -1500 | BR27: 1500 | CE27: -410030.68 | CG27: -98195.92
A28: =_xll.EPMOlapMemberO("[ACCOUNT].[PARENTH1].[303662]","","Machine Contra Revenue","","000") -> Machine Contra Revenue | U28: -365205 | V28: 365205
A29: =_xll.EPMOlapMemberO("[ACCOUNT].[PARENTH1].[303663]","","Contra Machine Discount Model","","000") -> Contra Machine Discount Model | U29: 98605.35 | V29: -98605.35
A30: =_xll.EPMOlapMemberO("[ACCOUNT].[PARENTH1].[303665]","","MPS Machine discount","","000") -> MPS Machine discount | AB30: -6000 | AD30: 2000 | AE30: 4000 | AG30: -5000 | AH30: 5000 | BO30: -1500 | BQ30: -2250 | BR30: 3750
A31: =_xll.EPMOlapMemberO("[ACCOUNT].[PARENTH1].[303671]","","New Non-Premium STL Discounts","","000") -> New Non-Premium STL Discounts | AH31: -48653 | AJ31: -52075.5 | AK31: -77826.25 | AM31: -11550 | AN31: -73605.75 | AO31: -163270.16 | AP31: 0 | AS31: -115136.5 | AV31: -54175.25 | AW31: -465513.73 | AX31: -157702 | AZ31: -756665.13 | BA31: -158003.42 | BB31: -271062 | BC31: -144187.5 | BD31: 20217.01 | BE31: -212945.25 | BF31: 77227.49 | BG31: -50556.25 | BH31: -30780 | BJ31: -15590 | BK31: -4995 | BM31: -166516.6 | BN31: -7873.66 | BO31: -173103.25 | BT31: -131449.25 | BW31: -12559.5 | BZ31: -29652.5 | CE31: -7143 | CF31: -72474.33
A32: =_xll.EPMOlapMemberO("[ACCOUNT].[PARENTH1].[303673]","","STL Disc Dfd Int - New Machines","","000") -> STL Disc Dfd Int - New Machines | BF32: -166566.99 | BG32: -86263 | BH32: -136525 | BJ32: -60727 | BK32: -24445 | BM32: -222091 | BN32: -73968 | BO32: -611940.01 | BQ32: -85403 | BR32: 271855.17 | BS32: -667637.77 | BT32: -151708 | BW32: 109204.2 | BX32: -23595 | BZ32: -26920 | CA32: -137316 | CE32: -3063 | CF32: -27162
A33: =_xll.EPMOlapMemberO("[ACCOUNT].[PARENTH1].[303668]","","New Machine Concession Distr_ExtPay","","000") -> New Machine Concession Distr_ExtPay
A34: =_xll.EPMOlapMemberO("[ACCOUNT].[PARENTH1].[RPTERMGAM2]","","Slot Terminals - New","","000") -> Slot Terminals - New | B34: =SUM(B11:B33) -> 6245016.6 | C34: =SUM(C11:C33) -> 6909238.1 | D34: =SUM(D11:D33) -> 47233203 | E34: =SUM(E11:E33) -> 8741238.8 | F34: =SUM(F11:F33) -> 16757634 | G34: =SUM(G11:G33) -> 44359688 | H34: =SUM(H11:H33) -> 9766846.5 | I34: =SUM(I11:I33) -> 16511283 | ... CG34: =SUM(CG11:CG33) -> 86505502
A35: =_xll.EPMOlapMemberO("[ACCOUNT].[PARENTH1].[303366]","","Used Non Premium STL Revenue","","000") -> Used Non Premium STL Revenue | AM35: 138600 | AP35: 286188.32 | AQ35: 283755.56 | BI35: 63862.53 | BJ35: -75007.5
A36: =_xll.EPMOlapMemberO("[ACCOUNT].[PARENTH1].[303653]","","Sales Disc USED Machines","","000") -> Sales Disc USED Machines | B36: -183423.66 | C36: -41537 | D36: -463216.53 | E36: -183671.6 | F36: -261905.86 | G36: -617641.7 | H36: -198851.24 | I36: -113598.37 | J36: -1007068 | K36: -163081.5 | L36: -428636.7 | M36: -768959.05 | N36: -144555.03 | O36: -220710.5 | P36: -448647.71 | R36: -365380 | S36: -450410.17 | T36: -256620.62 | U36: -117627.64 | V36: -456467.7 | W36: -371459.8 | X36: -319263.87 | Y36: -2222326 | Z36: -385160.97 | AA36: -338287.56 | AB36: -1004363 | AC36: -510376.35 | AD36: -720315.8 | AE36: -1727436.9 | AF36: -1171170 | AG36: -620310.82 | AH36: -1439756.2 | AI36: -450626.61 | AJ36: -702770.99 | AK36: -979182.07 | AL36: -402484.42 | AM36: -359821.9 | AN36: -440451.3 | AO36: -229187.09 | AP36: -265485.18 | AQ36: -812684.72 | AR36: -64295.7 | AS36: -156880.64 | AT36: -343946.44 | AU36: -146089.08 | AV36: -246057.35 | AW36: -745626.48 | AX36: -139605.59 | AY36: -71759.87 | AZ36: -153353.44 | BA36: -82279.5 | BB36: -105863.51 | BC36: -528663.73 | BD36: -499852.48 | BE36: -515598.38 | BF36: -673999.29 | BG36: -111234.36 | BH36: -299520.74 | BI36: -203779.95 | BJ36: -280692.59 | BK36: -100571.56 | BL36: -338009.91 | BM36: -131021.22 | BN36: -268281.83 | BO36: -457214.57 | BP36: -114251.09 | BQ36: -23438.27 | BR36: -793663.48 | BS36: -110456.6 | BT36: -97245.82 | BU36: -2568142.3 | BV36: -251922.2 | BW36: -657850.34 | BX36: -1494478.1 | BY36: -204141.62 | BZ36: -367362.62 | CA36: -1581171.3 | CB36: -1442921.7 | CC36: -411691.54 | CD36: -2047506.4 | CE36: 739987.07 | CF36: -2331049.5 | CG36: -529750.6
A37: =_xll.EPMOlapMemberO("[ACCOUNT].[PARENTH1].[303672]","","Used Non Premium STL Discounts","","000") -> Used Non Premium STL Discounts | AM37: -23100
A38: =_xll.EPMOlapMemberO("[ACCOUNT].[PARENTH1].[303654]","","USED Mach Discount Recovery","","000") -> USED Mach Discount Recovery
A39: =_xll.EPMOlapMemberO("[ACCOUNT].[PARENTH1].[303655]","","Disc Dfrd Int Mach USED","","000") -> Disc Dfrd Int Mach USED | BR39: -13376.11 | BX39: -41146.75 | CA39: -5284.7
A40: =_xll.EPMOlapMemberO("[ACCOUNT].[PARENTH1].[303656]","","USED Machine Concession","","000") -> USED Machine Concession
A41: =_xll.EPMOlapMemberO("[ACCOUNT].[PARENTH1].[303667]","","ETG Used Discount","","000") -> ETG Used Discount | AV41: -33747.75
...
