Workbook

Sheet AR Billing Folder

Sheet Pivot Summary
E2: =E3/E19 -> 0.04118532 | F2: =F3/F19 -> 0.023564008 | G2: =G3/G19 -> 0.019172144 | H2: =H3/H19 -> -0.016170325 | I2: =I3/I19 -> -0.016170325 | J2: =J3/J19 -> -0.016170325 | K2: =K3/K19 -> -0.052678197 | L2: =L3/L19 -> 0.034680943
B3: Diff | C3: =C19-C45 -> -28 | D3: =D19-D45 -> 0.051278842 | E3: =E19-E45 -> 7549555.1 | F3: =F19-F45 -> 303777.02 | G3: =G19-G45 -> 222932.33 | H3: =H19-H45 -> -20573.266 | I3: =I19-I45 -> -20573.266 | J3: =J19-J45 -> -20573.266 | ... L3: =L19-L45 -> 2.0569695
B5: End of Month Date | C5: (All)
J6: =GETPIVOTDATA("Sum of Net IGT Rev",$B$7)/GETPIVOTDATA("Sum of Machine Days",$B$7) -> 59.311234
B7: Row Labels | C7: Count of Serial Num | D7: Average of Par Split | E7: Sum of Coin In | F7: Sum of Gross Win | G7: Sum of Cust. Split | H7: Sum of IGT Split | I7: Sum of Gross IGT Rev | J7: Sum of Net IGT Rev | K7: Sum of Machine Days | L7: RPU | M7: Diff
A8: =B8=B34 -> TRUE | B8: 7th Street Casino | C8: 44 | D8: 0.2 | E8: 4803427.4 | F8: 370685.54 | G8: 296548.43 | H8: 74137.108 | I8: 74137.108 | J8: 74137.108 | K8: 1320 | L8: =J8/K8 -> 56.164476 | M8: =L8-L34 -> -1.1099805 | N8: Removed 10 Machines
A9: =B9=B35 -> TRUE | B9: Border Casino (Northern) | C9: 4 | D9: 0.1 | E9: 157059.6 | F9: 14008.39 | G9: 12607.551 | H9: 1400.839 | I9: 1400.839 | J9: 1400.839 | K9: 120 | L9: =J9/K9 -> 11.673658 | M9: =L9-L35 -> -0.83884973
A10: =B10=B36 -> TRUE | B10: Choctaw Durant Casino & Resort | C10: 8 | D10: 0.07875 | E10: 895044.54 | F10: 78431.41 | G10: 72254.936 | H10: 6176.4735 | I10: 6176.4735 | J10: 6176.4735 | K10: 248 | L10: =J10/K10 -> 24.905135 | M10: =L10-L36 -> 4.0759603 | N10: Gross Win increased
A11: =B11=B37 -> TRUE | B11: Choctaw Landing | C11: 9 | D11: 0.07875 | E11: 360085.82 | F11: 47214.3 | G11: 43496.174 | H11: 3718.1261 | I11: 3718.1261 | J11: 3718.1261 | K11: 270 | L11: =J11/K11 -> 13.770837 | M11: =L11-L37 -> 11.117061 | N11: Prior month - 3 of 9 machines have negative win due to JP's
A12: =B12=B38 -> TRUE | B12: Ho-Chunk Gaming Madison | C12: 150 | D12: 0.18 | E12: 28929478 | F12: 1314146 | G12: 1077599.7 | H12: 236546.28 | I12: 236546.28 | J12: 236546.28 | K12: 4499 | L12: =J12/K12 -> 52.577524 | M12: =L12-L38 -> -8.0618336 | N12: Removed 19 machines - Gross win decreased
A13: =B13=B39 -> TRUE | B13: Naskila Casino | C13: 40 | D13: 0.15 | E13: 15127229 | F13: 1001952 | G13: 852859.18 | H13: 149092.8 | I13: 149092.8 | J13: 149092.8 | K13: 1200 | L13: =J13/K13 -> 124.244 | M13: =L13-L39 -> 10.97317 | N13: Gross Win increased
A14: =B14=B40 -> TRUE | B14: Native Village of Eklutna | C14: 2 | D14: 0 | E14: 0 | F14: 0 | G14: 0 | H14: 3300 | I14: 3300 | J14: 3300 | K14: 60 | L14: =J14/K14 -> 55 | M14: =L14-L40 -> 11.25 | N14: Only 2 units active
A15: =B15=B41 -> TRUE | B15: Newcastle Gaming Center (Northern) | C15: 6 | D15: 0.1 | E15: 501661.2 | F15: 26743.1 | G15: 24068.79 | H15: 2674.31 | I15: 2674.31 | J15: 2674.31 | K15: 180 | L15: =J15/K15 -> 14.857278 | M15: =L15-L41 -> 2.6582455
A16: =B16=B42 -> TRUE | B16: OHIYA Casino Resort | C16: 42 | D16: 0.2 | E16: 274851 | F16: 72034.24 | G16: 61904.544 | H16: 15476.136 | I16: 15476.136 | J16: 15476.136 | K16: 1260 | L16: =J16/K16 -> 12.282648 | M16: =L16-L42 -> -0.50267343
A17: =B17=B43 -> TRUE | B17: San Pablo | C17: 421 | E17: 1.3149718e+08 | F17: 9912007.7 | G17: 9137679 | H17: 774328.64 | I17: 774328.64 | J17: 774328.64 | K17: 12144 | L17: =J17/K17 -> 63.76224 | M17: =L17-L43 -> 4.8187209 | N17: Added 15 units
A18: =B18=B44 -> TRUE | B18: WinStar World Casino | C18: 5 | D18: 0.1 | E18: 760930 | F18: 54345.59 | G18: 48911.031 | H18: 5434.559 | I18: 5434.559 | J18: 5434.559 | K18: 150 | L18: =J18/K18 -> 36.230393 | M18: =L18-L44 -> 1.1687224
B19: Grand Total | C19: 731 | D19: 0.17109274 | E19: 1.8330694e+08 | F19: 12891568 | G19: 11627929 | H19: 1272285.3 | I19: 1272285.3 | J19: 1272285.3 | K19: 21451 | L19: =J19/K19 -> 59.311234 | M19: =L19-L45 -> 2.0569695
B33: Row Labels | C33: Count of Serial Num | D33: Average of Par Split | E33: Sum of Coin In | F33: Sum of Gross Win | G33: Sum of Cust. Split | H33: Sum of IGT Split | I33: Sum of Gross IGT Rev | J33: Sum of Net IGT Rev | K33: Sum of Machine Days | L33: RPU | M33: Units | N33: Diff | O33: %
B34: 7th Street Casino | C34: 54 | D34: 0.2 | E34: 5642128.1 | F34: 402925.8 | G34: 332566.26 | H34: 80585.16 | I34: 80585.16 | J34: 80585.16 | K34: 1407 | L34: 57.274456 | M34: =VLOOKUP(B34,$B$3:$C$23,2,0) -> 44 | N34: =+M34-C34 -> -10 | O34: =N34/C34 -> -0.18518519
B35: Border Casino (Northern) | C35: 4 | D35: 0.1 | E35: 169908.6 | F35: 15515.51 | G35: 13963.959 | H35: 1551.551 | I35: 1551.551 | J35: 1551.551 | K35: 124 | L35: 12.512508 | M35: =VLOOKUP(B35,$B$3:$C$23,2,0) -> 4 | N35: =+M35-C35 -> 0 | O35: =N35/C35 -> 0
B36: Choctaw Durant Casino & Resort | C36: 8 | D36: 0.07875 | E36: 871583.66 | F36: 65595.37 | G36: 60429.735 | H36: 5165.6354 | I36: 5165.6354 | J36: 5165.6354 | K36: 248 | L36: 20.829175 | M36: =VLOOKUP(B36,$B$3:$C$23,2,0) -> 8 | N36: =+M36-C36 -> 0 | O36: =N36/C36 -> 0
B37: Choctaw Landing | C37: 9 | D37: 0.07875 | E37: 323901.77 | F37: 9401.95 | G37: 20419.718 | H37: 740.40356 | I37: 740.40356 | J37: 740.40356 | K37: 279 | L37: 2.6537762 | M37: =VLOOKUP(B37,$B$3:$C$23,2,0) -> 9 | N37: =+M37-C37 -> 0 | O37: =N37/C37 -> 0
B38: Ho-Chunk Gaming Madison | C38: 169 | D38: 0.18 | E38: 28877065 | F38: 1545966.7 | G38: 1296398 | H38: 278274.01 | I38: 278274.01 | J38: 278274.01 | K38: 4589 | L38: 60.639358 | M38: =VLOOKUP(B38,$B$3:$C$23,2,0) -> 150 | N38: =+M38-C38 -> -19 | O38: =N38/C38 -> -0.11242604
B39: Naskila Casino | C39: 40 | D39: 0.15 | E39: 14775809 | F39: 944638.84 | G39: 827722.3 | H39: 140455.83 | I39: 140455.83 | J39: 140455.83 | K39: 1240 | L39: 113.27083 | M39: =VLOOKUP(B39,$B$3:$C$23,2,0) -> 40 | N39: =+M39-C39 -> 0 | O39: =N39/C39 -> 0
B40: Native Village of Eklutna | C40: 16 | D40: 0 | E40: 0 | F40: 0 | G40: 0 | H40: 21700 | I40: 21700 | J40: 21700 | K40: 496 | L40: 43.75 | M40: =VLOOKUP(B40,$B$3:$C$23,2,0) -> 2 | N40: =+M40-C40 -> -14 | O40: =N40/C40 -> -0.875
B41: Newcastle Gaming Center (Northern) | C41: 6 | D41: 0.1 | E41: 524117.2 | F41: 22690.19 | G41: 26518.37 | H41: 2269.02 | I41: 2269.02 | J41: 2269.02 | K41: 186 | L41: 12.199032 | M41: =VLOOKUP(B41,$B$3:$C$23,2,0) -> 6 | N41: =+M41-C41 -> 0 | O41: =N41/C41 -> 0
B42: OHIYA Casino Resort | C42: 42 | D42: 0.2 | E42: 267528 | F42: 75193.58 | G42: 66585.952 | H42: 16646.488 | I42: 16646.488 | J42: 16646.488 | K42: 1302 | L42: 12.785321 | M42: =VLOOKUP(B42,$B$3:$C$23,2,0) -> 42 | N42: =+M42-C42 -> 0 | O42: =N42/C42 -> 0
B43: San Pablo | C43: 406 | D43: 0.08 | E43: 1.2360749e+08 | F43: 9451517.6 | G43: 8711481.8 | H43: 740035.88 | I43: 740035.88 | J43: 740035.88 | K43: 12555 | L43: 58.943519 | M43: =VLOOKUP(B43,$B$3:$C$23,2,0) -> 421 | N43: =+M43-C43 -> 15 | O43: =N43/C43 -> 0.036945813
B44: WinStar World Casino | C44: 5 | D44: 0.1 | E44: 697857.5 | F44: 54345.59 | G44: 48911.031 | H44: 5434.559 | I44: 5434.559 | J44: 5434.559 | K44: 155 | L44: 35.061671 | M44: =VLOOKUP(B44,$B$3:$C$23,2,0) -> 5 | N44: =+M44-C44 -> 0 | O44: =N44/C44 -> 0
B45: Grand Total | C45: 759 | D45: 0.1198139 | E45: 1.7575739e+08 | F45: 12587791 | G45: 11404997 | H45: 1292858.5 | I45: 1292858.5 | J45: 1292858.5 | K45: 22581 | L45: 57.254264

Sheet WP
B2: End of Month Date | C2: Install At | D2: Serial Num | E2: Coin In | F2: Gross Win | G2: Cust. Split | H2: IGT Split | I2: Gross IGT Rev | J2: Net IGT Rev | K2: Machine Days | L2: Par Split | M2: Cust Name (Ignore for SQL Upload) | O2: For Naskila - Use STARS Tab for Coin In | P2: See Lookup tab for Choctaw Cust #'s
B3: 45991 | C3: 3106723 | D3: 2109718 | E3: 139017.4 | F3: 11807.75 | G3: 9446.2 | H3: 2361.55 | I3: =H3 -> 2361.55 | J3: =I3 -> 2361.55 | K3: 30 | L3: 0.2 | M3: =VLOOKUP(C3,Lookup!B:C,2,0) -> 7th Street Casino
B4: =B3 -> 45991 | C4: 3106723 | D4: 2109719 | E4: 122923 | F4: 8294.54 | G4: 6635.632 | H4: 1658.908 | I4: =H4 -> 1658.908 | J4: =I4 -> 1658.908 | K4: 30 | L4: 0.2 | M4: =VLOOKUP(C4,Lookup!B:C,2,0) -> 7th Street Casino
B5: =B4 -> 45991 | C5: 3106723 | D5: 2109720 | E5: 78510.8 | F5: 3946.94 | G5: 3157.552 | H5: 789.388 | I5: =H5 -> 789.388 | J5: =I5 -> 789.388 | K5: 30 | L5: 0.2 | M5: =VLOOKUP(C5,Lookup!B:C,2,0) -> 7th Street Casino
B6: =B5 -> 45991 | C6: 3106723 | D6: 2109721 | E6: 81888 | F6: 3669.06 | G6: 2935.248 | H6: 733.812 | I6: =H6 -> 733.812 | J6: =I6 -> 733.812 | K6: 30 | L6: 0.2 | M6: =VLOOKUP(C6,Lookup!B:C,2,0) -> 7th Street Casino
B7: =B6 -> 45991 | C7: 3106723 | D7: 2185100 | E7: 114965.4 | F7: 10728.24 | G7: 8582.592 | H7: 2145.648 | I7: =H7 -> 2145.648 | J7: =I7 -> 2145.648 | K7: 30 | L7: 0.2 | M7: =VLOOKUP(C7,Lookup!B:C,2,0) -> 7th Street Casino
B8: =B7 -> 45991 | C8: 3106723 | D8: 2593737 | E8: 166937.1 | F8: 11424.53 | G8: 9139.624 | H8: 2284.906 | I8: =H8 -> 2284.906 | J8: =I8 -> 2284.906 | K8: 30 | L8: 0.2 | M8: =VLOOKUP(C8,Lookup!B:C,2,0) -> 7th Street Casino
B9: =B8 -> 45991 | C9: 3106723 | D9: 2593735 | E9: 144569.6 | F9: 13981.44 | G9: 11185.152 | H9: 2796.288 | I9: =H9 -> 2796.288 | J9: =I9 -> 2796.288 | K9: 30 | L9: 0.2 | M9: =VLOOKUP(C9,Lookup!B:C,2,0) -> 7th Street Casino
B10: =B9 -> 45991 | C10: 3106723 | D10: 2593738 | E10: 103229.98 | F10: 7525.88 | G10: 6020.704 | H10: 1505.176 | I10: =H10 -> 1505.176 | J10: =I10 -> 1505.176 | K10: 30 | L10: 0.2 | M10: =VLOOKUP(C10,Lookup!B:C,2,0) -> 7th Street Casino
B11: =B10 -> 45991 | C11: 3106723 | D11: 2593736 | E11: 121209.2 | F11: 8552.14 | G11: 6841.712 | H11: 1710.428 | I11: =H11 -> 1710.428 | J11: =I11 -> 1710.428 | K11: 30 | L11: 0.2 | M11: =VLOOKUP(C11,Lookup!B:C,2,0) -> 7th Street Casino
B12: =B11 -> 45991 | C12: 3106723 | D12: 2593739 | E12: 145271.94 | F12: 11050 | G12: 8840 | H12: 2210 | I12: =H12 -> 2210 | J12: =I12 -> 2210 | K12: 30 | L12: 0.2 | M12: =VLOOKUP(C12,Lookup!B:C,2,0) -> 7th Street Casino
B13: =B12 -> 45991 | C13: 3106723 | D13: 2623566 | E13: 122106.2 | F13: 10393.86 | G13: 8315.088 | H13: 2078.772 | I13: =H13 -> 2078.772 | J13: =I13 -> 2078.772 | K13: 30 | L13: 0.2 | M13: =VLOOKUP(C13,Lookup!B:C,2,0) -> 7th Street Casino
B14: =B13 -> 45991 | C14: 3106723 | D14: 2623567 | E14: 85880.6 | F14: 12700.53 | G14: 10160.424 | H14: 2540.106 | I14: =H14 -> 2540.106 | J14: =I14 -> 2540.106 | K14: 30 | L14: 0.2 | M14: =VLOOKUP(C14,Lookup!B:C,2,0) -> 7th Street Casino
B15: =B14 -> 45991 | C15: 3106723 | D15: 2623565 | E15: 53744.2 | F15: 597.2 | G15: 477.76 | H15: 119.44 | I15: =H15 -> 119.44 | J15: =I15 -> 119.44 | K15: 30 | L15: 0.2 | M15: =VLOOKUP(C15,Lookup!B:C,2,0) -> 7th Street Casino
... B46: =B45 -> 45991 | C46: 3106723 | D46: 2603550 | E46: 112122.75 | F46: 10649.24 | G46: 8519.392 | H46: 2129.848 | I46: =H46 -> 2129.848 | J46: =I46 -> 2129.848 | K46: 30 | L46: 0.2 | M46: =VLOOKUP(C46,Lookup!B:C,2,0) -> 7th Street Casino
B47: =B46 -> 45991 | C47: 3302859 | D47: 2531268 | E47: 113040 | F47: 11447.15 | G47: =+F47-H47 -> 10545.687 | H47: 901.46306 | I47: =H47 -> 901.46306 | J47: =I47 -> 901.46306 | K47: 31 | L47: 0.07875 | M47: =VLOOKUP(C47,Lookup!B:C,2,0) -> Choctaw Durant Casino & Resort
B48: =B47 -> 45991 | C48: 3302859 | D48: 2531264 | E48: 100079.22 | F48: 5637.02 | G48: =+F48-H48 -> 5193.1047 | H48: 443.91533 | I48: =H48 -> 443.91533 | J48: =I48 -> 443.91533 | K48: 31 | L48: 0.07875 | M48: =VLOOKUP(C48,Lookup!B:C,2,0) -> Choctaw Durant Casino & Resort
B49: =B48 -> 45991 | C49: 3302859 | D49: 2531269 | E49: 94682.62 | F49: 9355.97 | G49: =+F49-H49 -> 8619.1874 | H49: 736.78264 | I49: =H49 -> 736.78264 | J49: =I49 -> 736.78264 | K49: 31 | L49: 0.07875 | M49: =VLOOKUP(C49,Lookup!B:C,2,0) -> Choctaw Durant Casino & Resort
B50: =B49 -> 45991 | C50: 3302859 | D50: 2531265 | E50: 140952.5 | F50: 11984.95 | G50: =+F50-H50 -> 11041.135 | H50: 943.81481 | I50: =H50 -> 943.81481 | J50: =I50 -> 943.81481 | K50: 31 | L50: 0.07875 | M50: =VLOOKUP(C50,Lookup!B:C,2,0) -> Choctaw Durant Casino & Resort
B51: =B50 -> 45991 | C51: 3302859 | D51: 2531270 | E51: 115133.98 | F51: 14565.24 | G51: =+F51-H51 -> 13418.227 | H51: 1147.0127 | I51: =H51 -> 1147.0127 | J51: =I51 -> 1147.0127 | K51: 31 | L51: 0.07875 | M51: =VLOOKUP(C51,Lookup!B:C,2,0) -> Choctaw Durant Casino & Resort
B52: =B51 -> 45991 | C52: 3302859 | D52: 2531266 | E52: 88284.1 | F52: 3827.25 | G52: =+F52-H52 -> 3525.8541 | H52: 301.39594 | I52: =H52 -> 301.39594 | J52: =I52 -> 301.39594 | K52: 31 | L52: 0.07875 | M52: =VLOOKUP(C52,Lookup!B:C,2,0) -> Choctaw Durant Casino & Resort
B53: =B52 -> 45991 | C53: 3302859 | D53: 2531271 | E53: 101661.7 | F53: 6970.42 | G53: =+F53-H53 -> 6421.4994 | H53: 548.92057 | I53: =H53 -> 548.92057 | J53: =I53 -> 548.92057 | K53: 31 | L53: 0.07875 | M53: =VLOOKUP(C53,Lookup!B:C,2,0) -> Choctaw Durant Casino & Resort
B54: =B53 -> 45991 | C54: 3302859 | D54: 2531267 | E54: 141210.42 | F54: 14643.41 | G54: =+F54-H54 -> 13490.241 | H54: 1153.1685 | I54: =H54 -> 1153.1685 | J54: =I54 -> 1153.1685 | K54: 31 | L54: 0.07875 | M54: =VLOOKUP(C54,Lookup!B:C,2,0) -> Choctaw Durant Casino & Resort
B55: =B54 -> 45991 | C55: 3312495 | D55: 2607362 | E55: 38761.25 | F55: 6184.39 | G55: =+F55-H55 -> 5697.3693 | H55: 487.02071 | I55: =H55 -> 487.02071 | J55: =I55 -> 487.02071 | K55: 30 | L55: 0.07875 | M55: =VLOOKUP(C55,Lookup!B:C,2,0) -> Choctaw Landing
B56: =B55 -> 45991 | C56: 3312495 | D56: 2607360 | E56: 29252 | F56: 5602 | G56: =+F56-H56 -> 5160.8425 | H56: 441.1575 | I56: =H56 -> 441.1575 | J56: =I56 -> 441.1575 | K56: 30 | L56: 0.07875 | M56: =VLOOKUP(C56,Lookup!B:C,2,0) -> Choctaw Landing
B57: =B56 -> 45991 | C57: 3312495 | D57: 2607363 | E57: 37442.25 | F57: 3309.35 | G57: =+F57-H57 -> 3048.7387 | H57: 260.61131 | I57: =H57 -> 260.61131 | J57: =I57 -> 260.61131 | K57: 30 | L57: 0.07875 | M57: =VLOOKUP(C57,Lookup!B:C,2,0) -> Choctaw Landing
B58: =B57 -> 45991 | C58: 3312495 | D58: 2607364 | E58: 26745 | F58: 2056.98 | G58: =+F58-H58 -> 1894.9928 | H58: 161.98717 | I58: =H58 -> 161.98717 | J58: =I58 -> 161.98717 | K58: 30 | L58: 0.07875 | M58: =VLOOKUP(C58,Lookup!B:C,2,0) -> Choctaw Landing
... B63: =B62 -> 45991 | C63: 3312495 | D63: 2540253 | E63: 42226 | F63: 5726.85 | G63: =+F63-H63 -> 5275.8606 | H63: 450.98944 | I63: =H63 -> 450.98944 | J63: =I63 -> 450.98944 | K63: 30 | L63: 0.07875 | M63: =VLOOKUP(C63,Lookup!B:C,2,0) -> Choctaw Landing
B64: =B63 -> 45991 | C64: 3312907 | D64: 2648806 | E64: 0 | F64: 0 | G64: 0 | H64: 1650 | I64: =H64 -> 1650 | J64: =I64 -> 1650 | K64: 30 | L64: 0 | M64: =VLOOKUP(C64,Lookup!B:C,2,0) -> Native Village of Eklutna
B65: =B64 -> 45991 | C65: 3312907 | D65: 2648809 | E65: 0 | F65: 0 | G65: 0 | H65: 1650 | I65: =H65 -> 1650 | J65: =I65 -> 1650 | K65: 30 | L65: 0 | M65: =VLOOKUP(C65,Lookup!B:C,2,0) -> Native Village of Eklutna
B66: =B65 -> 45991 | C66: 3105048 | D66: 2251759 | E66: 163065 | F66: 8622.38 | G66: 7070.3516 | H66: 1552.0284 | I66: =H66 -> 1552.0284 | J66: =I66 -> 1552.0284 | K66: 30 | L66: 0.18 | M66: =VLOOKUP(C66,Lookup!B:C,2,0) -> Ho-Chunk Gaming Madison
B67: =B66 -> 45991 | C67: 3105048 | D67: 2640295 | E67: 188663.2 | F67: 7646.45 | G67: 6270.089 | H67: 1376.361 | I67: =H67 -> 1376.361 | J67: =I67 -> 1376.361 | K67: 30 | L67: 0.18 | M67: =VLOOKUP(C67,Lookup!B:C,2,0) -> Ho-Chunk Gaming Madison
B68: =B67 -> 45991 | C68: 3105048 | D68: 2640167 | E68: 176033 | F68: 16652.95 | G68: 13655.419 | H68: 2997.531 | I68: =H68 -> 2997.531 | J68: =I68 -> 2997.531 | K68: 30 | L68: 0.18 | M68: =VLOOKUP(C68,Lookup!B:C,2,0) -> Ho-Chunk Gaming Madison
B69: =B68 -> 45991 | C69: 3105048 | D69: 2583764 | E69: 194344.25 | F69: 2600.29 | G69: 2132.2378 | H69: 468.0522 | I69: =H69 -> 468.0522 | J69: =I69 -> 468.0522 | K69: 30 | L69: 0.18 | M69: =VLOOKUP(C69,Lookup!B:C,2,0) -> Ho-Chunk Gaming Madison
B70: =B69 -> 45991 | C70: 3105048 | D70: 2640165 | E70: 179753.13 | F70: 7844.76 | G70: 6432.7032 | H70: 1412.0568 | I70: =H70 -> 1412.0568 | J70: =I70 -> 1412.0568 | K70: 30 | L70: 0.18 | M70: =VLOOKUP(C70,Lookup!B:C,2,0) -> Ho-Chunk Gaming Madison
B71: =B70 -> 45991 | C71: 3105048 | D71: 2380161 | E71: 356724.5 | F71: 17479.09 | G71: 14332.854 | H71: 3146.2362 | I71: =H71 -> 3146.2362 | J71: =I71 -> 3146.2362 | K71: 30 | L71: 0.18 | M71: =VLOOKUP(C71,Lookup!B:C,2,0) -> Ho-Chunk Gaming Madison
B72: =B71 -> 45991 | C72: 3105048 | D72: 2505008 | E72: 133070.25 | F72: 9299.04 | G72: 7625.2128 | H72: 1673.8272 | I72: =H72 -> 1673.8272 | J72: =I72 -> 1673.8272 | K72: 30 | L72: 0.18 | M72: =VLOOKUP(C72,Lookup!B:C,2,0) -> Ho-Chunk Gaming Madison
B73: =B72 -> 45991 | C73: 3105048 | D73: 2587093 | E73: 341690.6 | F73: 20756.33 | G73: 17020.191 | H73: 3736.1394 | I73: =H73 -> 3736.1394 | J73: =I73 -> 3736.1394 | K73: 30 | L73: 0.18 | M73: =VLOOKUP(C73,Lookup!B:C,2,0) -> Ho-Chunk Gaming Madison
B74: =B73 -> 45991 | C74: 3105048 | D74: 2583762 | E74: 216461.4 | F74: 5303.71 | G74: 4349.0422 | H74: 954.6678 | I74: =H74 -> 954.6678 | J74: =I74 -> 954.6678 | K74: 30 | L74: 0.18 | M74: =VLOOKUP(C74,Lookup!B:C,2,0) -> Ho-Chunk Gaming Madison
B75: =B74 -> 45991 | C75: 3105048 | D75: 2585467 | E75: 98727.75 | F75: -1552.99 | G75: -1273.4518 | H75: -279.5382 | I75: =H75 -> -279.5382 | J75: =I75 -> -279.5382 | K75: 30 | L75: 0.18 | M75: =VLOOKUP(C75,Lookup!B:C,2,0) -> Ho-Chunk Gaming Madison
...

Sheet Billing Plan List
A1: Billing Plan Upload
B2: Row Labels | C2: Count of SERIAL NUM
B3: Angel of the Winds Casino | C3: 15
B4: Emerald Queen Casino Tacoma | C4: 16
B5: Little Creek Casino Resort | C5: 6
B6: Mistequa Casino Hotel | C6: 4
B7: Quil Ceda Creek Casino | C7: 18
B8: Skagit Valley Casino Resort | C8: 20
B9: Spokane Tribe Casino | C9: 14
B10: Tulalip Resort Casino | C10: 12
B11: Yakama Nation Legends Casino | C11: 179
B12: Silver Reef Casino | C12: 81
B13: Grand Total | C13: 365
A17: Follow up:
B18: Ko-Kwel - Moved to BO Reporting

Sheet Lookup
B1: Install At | C1: Cust Name (Ignore for SQL Upload)
B2: 3106723 | C2: 7th Street Casino
B3: 3104596 | C3: Angel of the Winds(Stillaguamish )
B4: 3302859 | C4: Choctaw Durant Casino & Resort | E4: Gaming Capital Group
B5: 3312495 | C5: Choctaw Landing | E5: Gaming Capital Group
B6: 3105246 | C6: Newcastle Gaming Center (Northern) | E6: Gaming Capital Group
B7: 3304946 | C7: Border Casino (Northern) | E7: Gaming Capital Group
B8: 3105234 | C8: WinStar World Casino | E8: Gaming Capital Group
B9: 3116516 | C9: Choctaw Landing (DNU) Use 3312495 per the PSD
B10: 3310485 | C10: Emerald Queen Casino Tacoma
B11: 3303597 | C11: Emerald Queen Hotel and Casino
B12: 3105048 | C12: Ho-Chunk Gaming Madison
B13: 3118328 | C13: Ilani Casino Resort
B14: 3122972 | C14: Ko-Kwel Casino Resort Medford
B15: 3121810 | C15: Lucky 77 Casino
B16: 3116101 | C16: Mechoopda Casino
B17: 3102469 | C17: Mistequa Casino Hotel
B18: 3101677 | C18: Muckleshoot Indian Casino
B19: 3118229 | C19: Naskila Casino
B20: 3102365 | C20: Northern Quest Casino
... B35: 3312907 | C35: Native Village of Eklutna
